<?xml version="1.0" ?>
<!-- =================================================================================== -->
<!-- |    This document was autogenerated by xacro from alfred_base_descr.urdf.xacro   | -->
<!-- |    EDITING THIS FILE BY HAND IS NOT RECOMMENDED                                 | -->
<!-- =================================================================================== -->
<robot name="alfred_base_descr">
  <!-- <xacro:alfred_base base_frame="world" base_pos_x="0.0" base_pos_y="0.0" base_pos_z="0.0" base_roll="0.0" base_pitch="0.0" base_yaw="0.0" r="0.8" g="0.8" b="0.8" a="1.0" /> -->
  <link name="local_world"/>
  <link name="base_center"/>
  <joint name="base_parent_joint" type="fixed">
    <parent link="local_world"/>
    <child link="base_center"/>
    <origin rpy="0 0 0" xyz="0 0 0"/>
  </joint>
  <link name="alfred_base_link">
    <visual>
      <origin rpy="0.0 0.0 0.0" xyz="0.0 0.0 0.0"/>
      <geometry>
        <mesh filename="package://dim_cpp/urdf/meshes/base-visual.stl" scale="0.001 0.001 0.001"/>
      </geometry>
      <material name="mat">
        <color rgba="0.8 0.8 0.8 1.0"/>
      </material>
    </visual>
    <collision>
      <origin rpy="0.0 0.0 0.0" xyz="0.0 0.0 0.0"/>
      <geometry>
        <mesh filename="package://dim_cpp/urdf/meshes/base-collision.stl" scale="0.001 0.001 0.001"/>
      </geometry>
      <material name="mat">
        <color rgba="0.8 0.8 0.8 1.0"/>
      </material>
    </collision>
    <inertial>
      <mass value="45"/>
      <inertia ixx="12.732327" ixy="0" ixz="0" iyy="12.513553" iyz="0" izz="1.8057749"/>
      <origin rpy="0 0 0" xyz=".225 -.2125 .9125"/>
    </inertial>
  </link>
  <joint name="base_center_joint" type="fixed">
    <parent link="base_center"/>
    <child link="alfred_base_link"/>
    <origin rpy="0 0 0" xyz="-.225 .2125 .1232"/>
  </joint>
  <link name="botwheel_right">
    <visual>
      <origin rpy="0 0 0" xyz="0 0 0"/>
      <geometry>
        <mesh filename="package://dim_cpp/urdf/meshes/botwheel-visual.stl" scale="0.001 0.001 0.001"/>
      </geometry>
      <material name="mat">
        <color rgba="0.8 0.8 0.8 1.0"/>
      </material>
    </visual>
    <collision>
      <origin rpy="0 0 0" xyz="0 0 0"/>
      <geometry>
        <mesh filename="package://dim_cpp/urdf/meshes/botwheel-collision.stl" scale="0.001 0.001 0.001"/>
      </geometry>
      <material name="mat">
        <color rgba="0.8 0.8 0.8 1.0"/>
      </material>
    </collision>
    <inertial>
      <mass value="2.2"/>
      <inertia ixx="0.006434956" ixy="0" ixz="0" iyy="0.01074723" iyz="0" izz="0.006435717"/>
    </inertial>
  </link>
  <joint name="right_wheel_joint" type="continuous">
    <parent link="alfred_base_link"/>
    <child link="botwheel_right"/>
    <origin rpy="0 0 -1.5707" xyz="-0.0561 -0.395 -0.0375"/>
    <axis xyz="0 1 0"/>
  </joint>
  <link name="botwheel_left">
    <visual>
      <origin rpy="0 0 0" xyz="0 0 0"/>
      <geometry>
        <mesh filename="package://dim_cpp/urdf/meshes/botwheel-visual.stl" scale="0.001 0.001 0.001"/>
      </geometry>
      <material name="mat">
        <color rgba="0.8 0.8 0.8 1.0"/>
      </material>
    </visual>
    <collision>
      <origin rpy="0 0 0" xyz="0 0 0"/>
      <geometry>
        <mesh filename="package://dim_cpp/urdf/meshes/botwheel-collision.stl" scale="0.001 0.001 0.001"/>
      </geometry>
      <material name="mat">
        <color rgba="0.8 0.8 0.8 1.0"/>
      </material>
    </collision>
    <inertial>
      <mass value="2.2"/>
      <inertia ixx="0.006434956" ixy="0" ixz="0" iyy="0.01074723" iyz="0" izz="0.006435717"/>
    </inertial>
  </link>
  <joint name="left_wheel_joint" type="continuous">
    <parent link="alfred_base_link"/>
    <child link="botwheel_left"/>
    <origin rpy="0 0 1.5707" xyz="0.5061 -0.395 -0.0375"/>
    <axis xyz="0 1 0"/>
  </joint>
  <link name="pillar_platform">
    <visual>
      <origin rpy="0 0 0" xyz="0 0 0"/>
      <geometry>
        <mesh filename="package://dim_cpp/urdf/meshes/pillarplatform-visual.stl" scale="0.001 0.001 0.001"/>
      </geometry>
      <material name="mat">
        <color rgba="0.8 0.8 0.8 1.0"/>
      </material>
    </visual>
    <collision>
      <origin rpy="0 0 0" xyz="0 0 0"/>
      <geometry>
        <mesh filename="package://dim_cpp/urdf/meshes/pillarplatform-collision.stl" scale="0.001 0.001 0.001"/>
      </geometry>
      <material name="mat">
        <color rgba="0.8 0.8 0.8 1.0"/>
      </material>
    </collision>
    <inertial>
      <mass value="1.5"/>
      <inertia ixx="0.008729344" ixy="0" ixz="0" iyy="0.0085796565" iyz="0" izz="0.01050275"/>
      <origin rpy="0 0 0" xyz=".225 -.365 1.41"/>
    </inertial>
  </link>
  <joint name="pillar_platform_joint" type="prismatic">
    <parent link="alfred_base_link"/>
    <child link="pillar_platform"/>
    <origin rpy="0 0 0" xyz="0 0 0"/>
    <axis xyz="0 0 1"/>
    <limit effort="100" lower="-0.83" upper="0.0" velocity="0.1"/>
  </joint>
  <link name="tilt_base">
    <visual>
      <origin rpy="0 0 0" xyz="-.225 .365 -1.645"/>
      <geometry>
        <mesh filename="package://dim_cpp/urdf/meshes/tiltbase-visual.stl" scale="0.001 0.001 0.001"/>
      </geometry>
      <material name="mat">
        <color rgba="0.8 0.8 0.8 1.0"/>
      </material>
    </visual>
    <collision>
      <origin rpy="0 0 0" xyz="-.225 .365 -1.645"/>
      <geometry>
        <mesh filename="package://dim_cpp/urdf/meshes/tiltbase-collision.stl" scale="0.001 0.001 0.001"/>
      </geometry>
      <material name="mat">
        <color rgba="0.8 0.8 0.8 1.0"/>
      </material>
    </collision>
    <inertial>
      <mass value=".15"/>
      <inertia ixx="8.479636e-05" ixy="0" ixz="0" iyy="0.00013581244" iyz="0" izz="0.0001717679"/>
    </inertial>
  </link>
  <joint name="pan_joint" type="revolute">
    <parent link="alfred_base_link"/>
    <child link="tilt_base"/>
    <origin rpy="0 0 0" xyz=".225 -.365 1.645"/>
    <axis xyz="0 0 1"/>
    <limit effort="100" lower="-1.57" upper="1.57" velocity="0.1"/>
  </joint>
  <link name="camera_holder">
    <visual>
      <origin rpy="0 0 0" xyz="-.225 .365 -1.659"/>
      <geometry>
        <mesh filename="package://dim_cpp/urdf/meshes/cameraholder-visual.stl" scale="0.001 0.001 0.001"/>
      </geometry>
      <material name="mat">
        <color rgba="0.8 0.8 0.8 1.0"/>
      </material>
    </visual>
    <collision>
      <origin rpy="0 0 0" xyz="-.225 .365 -1.659"/>
      <geometry>
        <mesh filename="package://dim_cpp/urdf/meshes/cameraholder-collision.stl" scale="0.001 0.001 0.001"/>
      </geometry>
      <material name="mat">
        <color rgba="0.8 0.8 0.8 1.0"/>
      </material>
    </collision>
    <inertial>
      <mass value=".05"/>
      <inertia ixx="3.1757907e-05" ixy="0" ixz="0" iyy="7.106668e-05" iyz="0" izz="4.4024575e-05"/>
      <origin rpy="0 0 0" xyz="0 0 .03"/>
    </inertial>
  </link>
  <joint name="tilt_joint" type="revolute">
    <parent link="tilt_base"/>
    <child link="camera_holder"/>
    <origin rpy="0 0 0" xyz="0 0 0.014"/>
    <axis xyz="1 0 0"/>
    <limit effort="100" lower="-1.57" upper="1.57" velocity="0.1"/>
  </joint>
  <link name="head_cam_link"/>
  <joint name="head_cam_joint" type="fixed">
    <parent link="camera_holder"/>
    <child link="head_cam_link"/>
    <origin rpy="0 0 0" xyz="0 -0.0025 0.057"/>
  </joint>
  <link name="chest_cam_link"/>
  <joint name="chest_cam_joint" type="fixed">
    <parent link="pillar_platform"/>
    <child link="chest_cam_link"/>
    <origin rpy="0.78539816 0 0" xyz=".225 -.455681 1.441731"/>
  </joint>
  <link name="right_arm_mount"/>
  <joint name="right_arm_mount_joint" type="fixed">
    <parent link="pillar_platform"/>
    <child link="right_arm_mount"/>
    <origin rpy="1.57079633 0 -1.57079633" xyz=".12325 -.319646 1.4125"/>
  </joint>
  <link name="left_arm_mount"/>
  <joint name="left_arm_mount_joint" type="fixed">
    <parent link="pillar_platform"/>
    <child link="left_arm_mount"/>
    <origin rpy="1.57079633 3.14159265 1.57079633" xyz=".32675 -.319646 1.4125"/>
  </joint>
  <!-- base_link of the sensor-->
  <link name="head_cam_frame"/>
  <joint name="head_cam_center_joint" type="fixed">
    <parent link="head_cam_link"/>
    <child link="head_cam_frame"/>
    <origin rpy="0 0 -1.5707963267948966" xyz="0 -0.022921 0.004764"/>
  </joint>
  <link name="head_cam_model_origin">
    <visual>
      <origin rpy="0 0 0" xyz="0 0 0"/>
      <geometry>
        <mesh filename="package://depthai_descriptions/urdf/models/OAK-D-PRO.stl"/>
      </geometry>
      <material name="mat">
        <color rgba="0.8 0.8 0.8 1.0"/>
      </material>
    </visual>
  </link>
  <joint name="head_cam_model_origin_joint" type="fixed">
    <parent link="head_cam_frame"/>
    <child link="head_cam_model_origin"/>
    <origin rpy="1.5708 0 1.5708" xyz="0 0 0"/>
  </joint>
  <!-- IMU -->
  <link name="head_cam_imu_frame"/>
  <joint name="head_cam_imu_joint" type="fixed">
    <parent link="head_cam_frame"/>
    <child link="head_cam_imu_frame"/>
    <origin rpy="3.141592653589793 1.5707963267948966 0.0" xyz="-0.008 -0.037945 -0.00079"/>
  </joint>
  <link name="head_cam_rgb_camera_frame"/>
  <joint name="head_cam_rgb_camera_joint" type="fixed">
    <parent link="head_cam_frame"/>
    <child link="head_cam_rgb_camera_frame"/>
    <origin rpy="0 0 0" xyz="0 0 0"/>
  </joint>
  <link name="head_cam_rgb_camera_optical_frame"/>
  <joint name="head_cam_rgb_camera_optical_joint" type="fixed">
    <origin rpy="-1.5707963267948966 0.0 -1.5707963267948966" xyz="0 0 0"/>
    <parent link="head_cam_rgb_camera_frame"/>
    <child link="head_cam_rgb_camera_optical_frame"/>
  </joint>
  <!-- Left Camera -->
  <link name="head_cam_left_camera_frame"/>
  <joint name="head_cam_left_camera_joint" type="fixed">
    <parent link="head_cam_frame"/>
    <child link="head_cam_left_camera_frame"/>
    <origin rpy="0 0 0" xyz="0 0.0375 0"/>
  </joint>
  <link name="head_cam_left_camera_optical_frame"/>
  <joint name="head_cam_left_camera_optical_joint" type="fixed">
    <origin rpy="-1.5707963267948966 0.0 -1.5707963267948966" xyz="0 0 0"/>
    <parent link="head_cam_left_camera_frame"/>
    <child link="head_cam_left_camera_optical_frame"/>
  </joint>
  <!-- right Camera -->
  <link name="head_cam_right_camera_frame"/>
  <joint name="head_cam_right_camera_joint" type="fixed">
    <parent link="head_cam_frame"/>
    <child link="head_cam_right_camera_frame"/>
    <origin rpy="0 0 0" xyz="0 -0.0375 0"/>
  </joint>
  <link name="head_cam_right_camera_optical_frame"/>
  <joint name="head_cam_right_camera_optical_joint" type="fixed">
    <origin rpy="-1.5707963267948966 0.0 -1.5707963267948966" xyz="0 0 0"/>
    <parent link="head_cam_right_camera_frame"/>
    <child link="head_cam_right_camera_optical_frame"/>
  </joint>
  <!-- base_link of the sensor-->
  <link name="chest_cam_frame"/>
  <joint name="chest_cam_center_joint" type="fixed">
    <parent link="chest_cam_link"/>
    <child link="chest_cam_frame"/>
    <origin rpy="3.14159265 0 -1.5707963267948966" xyz="0 -0.022921 -0.004764"/>
  </joint>
  <link name="chest_cam_model_origin">
    <visual>
      <origin rpy="0 0 0" xyz="0 0 0"/>
      <geometry>
        <mesh filename="package://depthai_descriptions/urdf/models/OAK-D-PRO.stl"/>
      </geometry>
      <material name="mat">
        <color rgba="0.8 0.8 0.8 1.0"/>
      </material>
    </visual>
  </link>
  <joint name="chest_cam_model_origin_joint" type="fixed">
    <parent link="chest_cam_frame"/>
    <child link="chest_cam_model_origin"/>
    <origin rpy="1.5708 0 1.5708" xyz="0 0 0"/>
  </joint>
  <!-- IMU -->
  <link name="chest_cam_imu_frame"/>
  <joint name="chest_cam_imu_joint" type="fixed">
    <parent link="chest_cam_frame"/>
    <child link="chest_cam_imu_frame"/>
    <origin rpy="3.141592653589793 1.5707963267948966 0.0" xyz="-0.008 -0.037945 -0.00079"/>
  </joint>
  <link name="chest_cam_rgb_camera_frame"/>
  <joint name="chest_cam_rgb_camera_joint" type="fixed">
    <parent link="chest_cam_frame"/>
    <child link="chest_cam_rgb_camera_frame"/>
    <origin rpy="0 0 0" xyz="0 0 0"/>
  </joint>
  <link name="chest_cam_rgb_camera_optical_frame"/>
  <joint name="chest_cam_rgb_camera_optical_joint" type="fixed">
    <origin rpy="-1.5707963267948966 0.0 -1.5707963267948966" xyz="0 0 0"/>
    <parent link="chest_cam_rgb_camera_frame"/>
    <child link="chest_cam_rgb_camera_optical_frame"/>
  </joint>
  <!-- Left Camera -->
  <link name="chest_cam_left_camera_frame"/>
  <joint name="chest_cam_left_camera_joint" type="fixed">
    <parent link="chest_cam_frame"/>
    <child link="chest_cam_left_camera_frame"/>
    <origin rpy="0 0 0" xyz="0 0.0375 0"/>
  </joint>
  <link name="chest_cam_left_camera_optical_frame"/>
  <joint name="chest_cam_left_camera_optical_joint" type="fixed">
    <origin rpy="-1.5707963267948966 0.0 -1.5707963267948966" xyz="0 0 0"/>
    <parent link="chest_cam_left_camera_frame"/>
    <child link="chest_cam_left_camera_optical_frame"/>
  </joint>
  <!-- right Camera -->
  <link name="chest_cam_right_camera_frame"/>
  <joint name="chest_cam_right_camera_joint" type="fixed">
    <parent link="chest_cam_frame"/>
    <child link="chest_cam_right_camera_frame"/>
    <origin rpy="0 0 0" xyz="0 -0.0375 0"/>
  </joint>
  <link name="chest_cam_right_camera_optical_frame"/>
  <joint name="chest_cam_right_camera_optical_joint" type="fixed">
    <origin rpy="-1.5707963267948966 0.0 -1.5707963267948966" xyz="0 0 0"/>
    <parent link="chest_cam_right_camera_frame"/>
    <child link="chest_cam_right_camera_optical_frame"/>
  </joint>
  <!-- Insert at the beginning of xarm_device_macro.xacro -->
  <material name="right_Black">
    <color rgba="0.0 0.0 0.0 1.0"/>
  </material>
  <material name="right_Red">
    <color rgba="0.8 0.0 0.0 1.0"/>
  </material>
  <material name="right_White">
    <color rgba="1.0 1.0 1.0 1.0"/>
  </material>
  <material name="right_Silver">
    <color rgba="0.753 0.753 0.753 1.0"/>
  </material>
  <joint name="right_world_joint" type="fixed">
    <parent link="right_arm_mount"/>
    <child link="right_link_base"/>
    <origin rpy="0 0 0" xyz="0 0 0"/>
  </joint>
  <ros2_control name="right_uf_robot_hardware/UFRobotFakeSystemHardware" type="system">
    <hardware>
      <plugin>uf_robot_hardware/UFRobotFakeSystemHardware</plugin>
      <!-- fake -->
      <!-- <plugin>fake_components/GenericSystem</plugin> -->
      <!-- gazebo -->
      <!-- <plugin>gazebo_ros2_control/GazeboSystem</plugin> -->
      <!-- real xarm -->
      <!-- <plugin>uf_robot_hardware/UFRobotSystemHardware</plugin> -->
    </hardware>
    <joint name="right_joint1">
      <command_interface name="position">
        <param name="min">-6.283185307179586</param>
        <param name="max">6.283185307179586</param>
      </command_interface>
      <command_interface name="velocity">
        <param name="min">-3.14</param>
        <param name="max">3.14</param>
      </command_interface>
      <state_interface name="position"/>
      <state_interface name="velocity"/>
      <!-- <state_interface name="effort"/> -->
    </joint>
    <joint name="right_joint2">
      <command_interface name="position">
        <param name="min">-2.059</param>
        <param name="max">2.0944</param>
      </command_interface>
      <command_interface name="velocity">
        <param name="min">-3.14</param>
        <param name="max">3.14</param>
      </command_interface>
      <state_interface name="position"/>
      <state_interface name="velocity"/>
      <!-- <state_interface name="effort"/> -->
    </joint>
    <joint name="right_joint3">
      <command_interface name="position">
        <param name="min">-3.927</param>
        <param name="max">0.19198</param>
      </command_interface>
      <command_interface name="velocity">
        <param name="min">-3.14</param>
        <param name="max">3.14</param>
      </command_interface>
      <state_interface name="position"/>
      <state_interface name="velocity"/>
      <!-- <state_interface name="effort"/> -->
    </joint>
    <joint name="right_joint4">
      <command_interface name="position">
        <param name="min">-6.283185307179586</param>
        <param name="max">6.283185307179586</param>
      </command_interface>
      <command_interface name="velocity">
        <param name="min">-3.14</param>
        <param name="max">3.14</param>
      </command_interface>
      <state_interface name="position"/>
      <state_interface name="velocity"/>
      <!-- <state_interface name="effort"/> -->
    </joint>
    <joint name="right_joint5">
      <command_interface name="position">
        <param name="min">-1.69297</param>
        <param name="max">3.141592653589793</param>
      </command_interface>
      <command_interface name="velocity">
        <param name="min">-3.14</param>
        <param name="max">3.14</param>
      </command_interface>
      <state_interface name="position"/>
      <state_interface name="velocity"/>
      <!-- <state_interface name="effort"/> -->
    </joint>
    <joint name="right_joint6">
      <command_interface name="position">
        <param name="min">-6.283185307179586</param>
        <param name="max">6.283185307179586</param>
      </command_interface>
      <command_interface name="velocity">
        <param name="min">-3.14</param>
        <param name="max">3.14</param>
      </command_interface>
      <state_interface name="position"/>
      <state_interface name="velocity"/>
      <!-- <state_interface name="effort"/> -->
    </joint>
  </ros2_control>
  <link name="right_link_base">
    <inertial>
      <origin rpy="0 0 0" xyz="0.0 0.0 0.09103"/>
      <mass value="2.7"/>
      <inertia ixx="0.00494875" ixy="-3.5E-06" ixz="1.25E-05" iyy="0.00494174" iyz="1.67E-06" izz="0.002219"/>
    </inertial>
    <visual>
      <geometry>
        <mesh filename="package://xarm_description/meshes/xarm6/visual/link_base.stl"/>
      </geometry>
      <origin rpy="0 0 0" xyz="0 0 0"/>
      <material name="right_White"/>
    </visual>
    <collision>
      <geometry>
        <mesh filename="package://xarm_description/meshes/xarm6/visual/link_base.stl"/>
      </geometry>
      <origin rpy="0 0 0" xyz="0 0 0"/>
    </collision>
  </link>
  <link name="right_link1">
    <inertial>
      <origin rpy="0 0 0" xyz="0.00022 0.02951 -0.0124"/>
      <mass value="2.3814"/>
      <inertia ixx="0.0058562" ixy="-1.79e-05" ixz="3.55e-06" iyy="0.0050316" iyz="-0.000888336" izz="0.003536652"/>
    </inertial>
    <visual>
      <geometry>
        <mesh filename="package://xarm_description/meshes/xarm6/visual/link1.stl"/>
      </geometry>
      <origin rpy="0 0 0" xyz="0 0 0"/>
      <material name="right_White"/>
    </visual>
    <collision>
      <geometry>
        <mesh filename="package://xarm_description/meshes/xarm6/visual/link1.stl"/>
      </geometry>
      <origin rpy="0 0 0" xyz="0 0 0"/>
    </collision>
  </link>
  <joint name="right_joint1" type="revolute">
    <parent link="right_link_base"/>
    <child link="right_link1"/>
    <origin rpy="0 0 0" xyz="0 0 0.267"/>
    <axis xyz="0 0 1"/>
    <limit effort="50.0" lower="-6.283185307179586" upper="6.283185307179586" velocity="3.14"/>
    <dynamics damping="1.0" friction="1.0"/>
  </joint>
  <link name="right_link2">
    <inertial>
      <origin rpy="0 0 0" xyz="0.03881 -0.22783 0.03496"/>
      <mass value="2.2675"/>
      <inertia ixx="0.028315776" ixy="0.005" ixz="0.00066546" iyy="0.0058" iyz="-0.0045741" izz="0.0273447"/>
    </inertial>
    <visual>
      <geometry>
        <mesh filename="package://xarm_description/meshes/xarm6/visual/link2.stl"/>
      </geometry>
      <origin rpy="0 0 0" xyz="0 0 0"/>
      <material name="right_White"/>
    </visual>
    <collision>
      <geometry>
        <mesh filename="package://xarm_description/meshes/xarm6/visual/link2.stl"/>
      </geometry>
      <origin rpy="0 0 0" xyz="0 0 0"/>
    </collision>
  </link>
  <joint name="right_joint2" type="revolute">
    <parent link="right_link1"/>
    <child link="right_link2"/>
    <origin rpy="-1.5708 0 0" xyz="0 0 0"/>
    <axis xyz="0 0 1"/>
    <limit effort="50.0" lower="-2.059" upper="2.0944" velocity="3.14"/>
    <dynamics damping="1.0" friction="1.0"/>
  </joint>
  <link name="right_link3">
    <inertial>
      <origin rpy="0 0 0" xyz="0.07041 0.11631 0.0107"/>
      <mass value="1.875"/>
      <inertia ixx="0.0063483" ixy="-0.0015397" ixz="0.00096858" iyy="0.00379758" iyz="0.00186567" izz="0.00595768"/>
    </inertial>
    <visual>
      <geometry>
        <mesh filename="package://xarm_description/meshes/xarm6/visual/link3.stl"/>
      </geometry>
      <origin rpy="0 0 0" xyz="0 0 0"/>
      <material name="right_White"/>
    </visual>
    <collision>
      <geometry>
        <mesh filename="package://xarm_description/meshes/xarm6/visual/link3.stl"/>
      </geometry>
      <origin rpy="0 0 0" xyz="0 0 0"/>
    </collision>
  </link>
  <joint name="right_joint3" type="revolute">
    <parent link="right_link2"/>
    <child link="right_link3"/>
    <origin rpy="0 0 0" xyz="0.0535 -0.2845 0"/>
    <axis xyz="0 0 1"/>
    <limit effort="32.0" lower="-3.927" upper="0.19198" velocity="3.14"/>
    <dynamics damping="1.0" friction="1.0"/>
  </joint>
  <link name="right_link4">
    <inertial>
      <origin rpy="0 0 0" xyz="-0.00018 0.01798 -0.02291"/>
      <mass value="1.3192"/>
      <inertia ixx="0.004896" ixy="-6.925e-06" ixz="-1.418e-05" iyy="0.00445694" iyz="-0.00023186" izz="0.00134332"/>
    </inertial>
    <visual>
      <geometry>
        <mesh filename="package://xarm_description/meshes/xarm6/visual/link4.stl"/>
      </geometry>
      <origin rpy="0 0 0" xyz="0 0 0"/>
      <material name="right_White"/>
    </visual>
    <collision>
      <geometry>
        <mesh filename="package://xarm_description/meshes/xarm6/visual/link4.stl"/>
      </geometry>
      <origin rpy="0 0 0" xyz="0 0 0"/>
    </collision>
  </link>
  <joint name="right_joint4" type="revolute">
    <parent link="right_link3"/>
    <child link="right_link4"/>
    <origin rpy="-1.5708 0 0" xyz="0.0775 0.3425 0"/>
    <axis xyz="0 0 1"/>
    <limit effort="32.0" lower="-6.283185307179586" upper="6.283185307179586" velocity="3.14"/>
    <dynamics damping="1.0" friction="1.0"/>
  </joint>
  <link name="right_link5">
    <inertial>
      <origin rpy="0 0 0" xyz="0.0651 0.03096 0.00315"/>
      <mass value="1.33854"/>
      <inertia ixx="0.00146378" ixy="-0.000450624" ixz="0.000284306" iyy="0.00184192" iyz="0.000130866" izz="0.002333524"/>
    </inertial>
    <visual>
      <geometry>
        <mesh filename="package://xarm_description/meshes/xarm6/visual/link5.stl"/>
      </geometry>
      <origin rpy="0 0 0" xyz="0 0 0"/>
      <material name="right_White"/>
    </visual>
    <collision>
      <geometry>
        <mesh filename="package://xarm_description/meshes/xarm6/visual/link5.stl"/>
      </geometry>
      <origin rpy="0 0 0" xyz="0 0 0"/>
    </collision>
  </link>
  <joint name="right_joint5" type="revolute">
    <parent link="right_link4"/>
    <child link="right_link5"/>
    <origin rpy="1.5708 0 0" xyz="0 0 0"/>
    <axis xyz="0 0 1"/>
    <limit effort="32.0" lower="-1.69297" upper="3.141592653589793" velocity="3.14"/>
    <dynamics damping="1.0" friction="1.0"/>
  </joint>
  <link name="right_link6">
    <inertial>
      <origin rpy="0 0 0" xyz="0 -0.00677 -0.01098"/>
      <mass value="0.17"/>
      <inertia ixx="9.3e-05" ixy="-0.0" ixz="-0.0" iyy="5.87e-05" iyz="-3.6e-06" izz="0.000132"/>
    </inertial>
    <visual>
      <geometry>
        <mesh filename="package://xarm_description/meshes/xarm6/visual/link6.stl"/>
      </geometry>
      <origin rpy="0 0 0" xyz="0 0 0"/>
      <material name="right_Silver"/>
    </visual>
    <collision>
      <geometry>
        <mesh filename="package://xarm_description/meshes/end_tool/collision/end_tool.stl"/>
      </geometry>
      <origin rpy="0 0 0" xyz="0 0 0"/>
    </collision>
  </link>
  <joint name="right_joint6" type="revolute">
    <parent link="right_link5"/>
    <child link="right_link6"/>
    <origin rpy="-1.5708 0 0" xyz="0.076 0.097 0"/>
    <axis xyz="0 0 1"/>
    <limit effort="20.0" lower="-6.283185307179586" upper="6.283185307179586" velocity="3.14"/>
    <dynamics damping="1.0" friction="1.0"/>
  </joint>
  <!-- <link name="${prefix}link_eef" />
    <joint name="${prefix}joint_eef" type="fixed">
      <origin xyz="0 0 0" rpy="0 0 0" />
      <parent link="${prefix}link6" />
      <child link="${prefix}link_eef" />
    </joint> -->
  <transmission name="right_tran1">
    <type>transmission_interface/SimpleTransmission</type>
    <joint name="right_joint1">
      <hardwareInterface>hardware_interface/PositionJointInterface</hardwareInterface>
    </joint>
    <actuator name="right_motor1">
      <hardwareInterface>hardware_interface/PositionJointInterface</hardwareInterface>
      <mechanicalReduction>100</mechanicalReduction>
    </actuator>
  </transmission>
  <transmission name="right_tran2">
    <type>transmission_interface/SimpleTransmission</type>
    <joint name="right_joint2">
      <hardwareInterface>hardware_interface/PositionJointInterface</hardwareInterface>
    </joint>
    <actuator name="right_motor2">
      <hardwareInterface>hardware_interface/PositionJointInterface</hardwareInterface>
      <mechanicalReduction>100</mechanicalReduction>
    </actuator>
  </transmission>
  <transmission name="right_tran3">
    <type>transmission_interface/SimpleTransmission</type>
    <joint name="right_joint3">
      <hardwareInterface>hardware_interface/PositionJointInterface</hardwareInterface>
    </joint>
    <actuator name="right_motor3">
      <hardwareInterface>hardware_interface/PositionJointInterface</hardwareInterface>
      <mechanicalReduction>100</mechanicalReduction>
    </actuator>
  </transmission>
  <transmission name="right_tran4">
    <type>transmission_interface/SimpleTransmission</type>
    <joint name="right_joint4">
      <hardwareInterface>hardware_interface/PositionJointInterface</hardwareInterface>
    </joint>
    <actuator name="right_motor4">
      <hardwareInterface>hardware_interface/PositionJointInterface</hardwareInterface>
      <mechanicalReduction>100</mechanicalReduction>
    </actuator>
  </transmission>
  <transmission name="right_tran5">
    <type>transmission_interface/SimpleTransmission</type>
    <joint name="right_joint5">
      <hardwareInterface>hardware_interface/PositionJointInterface</hardwareInterface>
    </joint>
    <actuator name="right_motor5">
      <hardwareInterface>hardware_interface/PositionJointInterface</hardwareInterface>
      <mechanicalReduction>100</mechanicalReduction>
    </actuator>
  </transmission>
  <transmission name="right_tran6">
    <type>transmission_interface/SimpleTransmission</type>
    <joint name="right_joint6">
      <hardwareInterface>hardware_interface/PositionJointInterface</hardwareInterface>
    </joint>
    <actuator name="right_motor6">
      <hardwareInterface>hardware_interface/PositionJointInterface</hardwareInterface>
      <mechanicalReduction>100</mechanicalReduction>
    </actuator>
  </transmission>
  <gazebo reference="right_link_base">
    <selfCollide>true</selfCollide>
  </gazebo>
  <gazebo reference="right_link1">
    <selfCollide>true</selfCollide>
  </gazebo>
  <gazebo reference="right_link2">
    <selfCollide>true</selfCollide>
  </gazebo>
  <gazebo reference="right_link3">
    <selfCollide>true</selfCollide>
  </gazebo>
  <gazebo reference="right_link4">
    <selfCollide>true</selfCollide>
  </gazebo>
  <gazebo reference="right_link5">
    <selfCollide>true</selfCollide>
  </gazebo>
  <gazebo reference="right_link6">
    <selfCollide>true</selfCollide>
  </gazebo>
  <link name="right_link_eef"/>
  <joint name="right_joint_eef" type="fixed">
    <origin rpy="0 0 0" xyz="0 0 0"/>
    <parent link="right_link6"/>
    <child link="right_link_eef"/>
  </joint>
  <ros2_control name="right_XArmGripperSystem" type="system">
    <hardware>
      <plugin>uf_robot_hardware/UFRobotFakeSystemHardware</plugin>
    </hardware>
    <joint name="right_drive_joint">
      <command_interface name="position">
        </command_interface>
      <command_interface name="velocity">
        <param name="min">-3.14</param>
        <param name="max">3.14</param>
      </command_interface>
      <state_interface name="position"/>
      <state_interface name="velocity"/>
      <!-- <state_interface name="effort"/> -->
    </joint>
  </ros2_control>
  <joint name="right_gripper_fix" type="fixed">
    <parent link="right_link_eef"/>
    <child link="right_xarm_gripper_base_link"/>
    <origin rpy="0 0 0" xyz="0 0 0"/>
  </joint>
  <link name="right_xarm_gripper_base_link">
    <inertial>
      <origin rpy="0 0 0" xyz="-0.00065489 -0.0018497 0.048028"/>
      <mass value="0.54156"/>
      <inertia ixx="0.00047106" ixy="3.9292E-07" ixz="2.6537E-06" iyy="0.00033072" iyz="-1.0975E-05" izz="0.00025642"/>
    </inertial>
    <visual>
      <geometry>
        <mesh filename="package://xarm_description/meshes/gripper/xarm/base_link.stl"/>
      </geometry>
      <origin rpy="0 0 0" xyz="0 0 0"/>
      <material name="right_White"/>
    </visual>
    <collision>
      <geometry>
        <mesh filename="package://xarm_description/meshes/gripper/xarm/base_link.stl"/>
      </geometry>
      <origin rpy="0 0 0" xyz="0 0 0"/>
    </collision>
  </link>
  <link name="right_left_outer_knuckle">
    <inertial>
      <origin rpy="0 0 0" xyz="2.9948E-14 0.021559 0.015181"/>
      <mass value="0.033618"/>
      <inertia ixx="1.9111E-05" ixy="-1.8803E-17" ixz="-1.1002E-17" iyy="6.6256E-06" iyz="-7.3008E-06" izz="1.3185E-05"/>
    </inertial>
    <visual>
      <geometry>
        <mesh filename="package://xarm_description/meshes/gripper/xarm/left_outer_knuckle.stl"/>
      </geometry>
      <origin rpy="0 0 0" xyz="0 0 0"/>
      <material name="right_Silver"/>
    </visual>
    <collision>
      <geometry>
        <mesh filename="package://xarm_description/meshes/gripper/xarm/left_outer_knuckle.stl"/>
      </geometry>
      <origin rpy="0 0 0" xyz="0 0 0"/>
    </collision>
  </link>
  <joint name="right_drive_joint" type="revolute">
    <origin rpy="0 0 0" xyz="0 0.035 0.059098"/>
    <parent link="right_xarm_gripper_base_link"/>
    <child link="right_left_outer_knuckle"/>
    <axis xyz="1 0 0"/>
    <limit effort="50" lower="0.0" upper="0.85" velocity="2.0"/>
  </joint>
  <link name="right_left_finger">
    <inertial>
      <origin rpy="0 0 0" xyz="-2.4536E-14 -0.016413 0.029258"/>
      <mass value="0.048304"/>
      <inertia ixx="1.7493E-05" ixy="-4.2156E-19" ixz="6.9164E-18" iyy="1.7225E-05" iyz="4.6433E-06" izz="5.1466E-06"/>
    </inertial>
    <visual>
      <geometry>
        <mesh filename="package://xarm_description/meshes/gripper/xarm/left_finger.stl"/>
      </geometry>
      <origin rpy="0 0 0" xyz="0 0 0"/>
      <material name="right_Silver"/>
    </visual>
    <collision>
      <geometry>
        <mesh filename="package://xarm_description/meshes/gripper/xarm/left_finger.stl"/>
      </geometry>
      <origin rpy="0 0 0" xyz="0 0 0"/>
    </collision>
  </link>
  <joint name="right_left_finger_joint" type="revolute">
    <origin rpy="0 0 0" xyz="0 0.035465 0.042039"/>
    <parent link="right_left_outer_knuckle"/>
    <child link="right_left_finger"/>
    <axis xyz="-1 0 0"/>
    <limit effort="50" lower="0.0" upper="0.85" velocity="2.0"/>
    <mimic joint="right_drive_joint" multiplier="1" offset="0"/>
  </joint>
  <link name="right_left_inner_knuckle">
    <inertial>
      <origin rpy="0 0 0" xyz="1.86600784687907E-06 0.0220467847633621 0.0261334672830885"/>
      <mass value="0.0230125781256706"/>
      <inertia ixx="6.09490024271906E-06" ixy="6.06651326160071E-11" ixz="7.19102670500635E-11" iyy="6.01955084375188E-06" iyz="-2.75316812991721E-06" izz="5.07862004479903E-06"/>
    </inertial>
    <visual>
      <geometry>
        <mesh filename="package://xarm_description/meshes/gripper/xarm/left_inner_knuckle.stl"/>
      </geometry>
      <origin rpy="0 0 0" xyz="0 0 0"/>
      <material name="right_Silver"/>
    </visual>
    <collision>
      <geometry>
        <mesh filename="package://xarm_description/meshes/gripper/xarm/left_inner_knuckle.stl"/>
      </geometry>
      <origin rpy="0 0 0" xyz="0 0 0"/>
    </collision>
  </link>
  <joint name="right_left_inner_knuckle_joint" type="revolute">
    <origin rpy="0 0 0" xyz="0 0.02 0.074098"/>
    <parent link="right_xarm_gripper_base_link"/>
    <child link="right_left_inner_knuckle"/>
    <axis xyz="1 0 0"/>
    <limit effort="50" lower="0" upper="0.85" velocity="2"/>
    <mimic joint="right_drive_joint" multiplier="1" offset="0"/>
  </joint>
  <link name="right_right_outer_knuckle">
    <inertial>
      <origin rpy="0 0 0" xyz="-3.1669E-14 -0.021559 0.015181"/>
      <mass value="0.033618"/>
      <inertia ixx="1.9111E-05" ixy="-1.8789E-17" ixz="1.0986E-17" iyy="6.6256E-06" iyz="7.3008E-06" izz="1.3185E-05"/>
    </inertial>
    <visual>
      <geometry>
        <mesh filename="package://xarm_description/meshes/gripper/xarm/right_outer_knuckle.stl"/>
      </geometry>
      <origin rpy="0 0 0" xyz="0 0 0"/>
      <material name="right_Silver"/>
    </visual>
    <collision>
      <geometry>
        <mesh filename="package://xarm_description/meshes/gripper/xarm/right_outer_knuckle.stl"/>
      </geometry>
      <origin rpy="0 0 0" xyz="0 0 0"/>
    </collision>
  </link>
  <joint name="right_right_outer_knuckle_joint" type="revolute">
    <origin rpy="0 0 0" xyz="0 -0.035 0.059098"/>
    <parent link="right_xarm_gripper_base_link"/>
    <child link="right_right_outer_knuckle"/>
    <axis xyz="-1 0 0"/>
    <limit effort="50" lower="0" upper="0.85" velocity="2"/>
    <mimic joint="right_drive_joint" multiplier="1" offset="0"/>
  </joint>
  <link name="right_right_finger">
    <inertial>
      <origin rpy="0 0 0" xyz="2.5618E-14 0.016413 0.029258"/>
      <mass value="0.048304"/>
      <inertia ixx="1.7493E-05" ixy="-5.0014E-19" ixz="-7.5079E-18" iyy="1.7225E-05" iyz="-4.6435E-06" izz="5.1466E-06"/>
    </inertial>
    <visual>
      <geometry>
        <mesh filename="package://xarm_description/meshes/gripper/xarm/right_finger.stl"/>
      </geometry>
      <origin rpy="0 0 0" xyz="0 0 0"/>
      <material name="right_Silver"/>
    </visual>
    <collision>
      <geometry>
        <mesh filename="package://xarm_description/meshes/gripper/xarm/right_finger.stl"/>
      </geometry>
      <origin rpy="0 0 0" xyz="0 0 0"/>
    </collision>
  </link>
  <joint name="right_right_finger_joint" type="revolute">
    <origin rpy="0 0 0" xyz="0 -0.035465 0.042039"/>
    <parent link="right_right_outer_knuckle"/>
    <child link="right_right_finger"/>
    <axis xyz="1 0 0"/>
    <limit effort="50" lower="0" upper="0.85" velocity="2"/>
    <mimic joint="right_drive_joint" multiplier="1" offset="0"/>
  </joint>
  <link name="right_right_inner_knuckle">
    <inertial>
      <origin rpy="0 0 0" xyz="1.866E-06 -0.022047 0.026133"/>
      <mass value="0.023013"/>
      <inertia ixx="6.0949E-06" ixy="-6.0665E-11" ixz="7.191E-11" iyy="6.0197E-06" iyz="2.7531E-06" izz="5.0784E-06"/>
    </inertial>
    <visual>
      <geometry>
        <mesh filename="package://xarm_description/meshes/gripper/xarm/right_inner_knuckle.stl"/>
      </geometry>
      <origin rpy="0 0 0" xyz="0 0 0"/>
      <material name="right_Silver"/>
    </visual>
    <collision>
      <geometry>
        <mesh filename="package://xarm_description/meshes/gripper/xarm/right_inner_knuckle.stl"/>
      </geometry>
      <origin rpy="0 0 0" xyz="0 0 0"/>
    </collision>
  </link>
  <joint name="right_right_inner_knuckle_joint" type="revolute">
    <origin rpy="0 0 0" xyz="0 -0.02 0.074098"/>
    <parent link="right_xarm_gripper_base_link"/>
    <child link="right_right_inner_knuckle"/>
    <axis xyz="-1 0 0"/>
    <limit effort="50" lower="0" upper="0.85" velocity="2"/>
    <mimic joint="right_drive_joint" multiplier="1" offset="0"/>
  </joint>
  <link name="right_link_tcp"/>
  <joint name="right_joint_tcp" type="fixed">
    <origin rpy="0 0 0" xyz="0 0 0.172"/>
    <parent link="right_xarm_gripper_base_link"/>
    <child link="right_link_tcp"/>
  </joint>
  <transmission name="right_drive_joint_trans">
    <type>transmission_interface/SimpleTransmission</type>
    <joint name="right_drive_joint">
      <hardwareInterface>hardware_interface/PositionJointInterface</hardwareInterface>
    </joint>
    <actuator name="right_drive_joint_motor">
      <hardwareInterface>hardware_interface/PositionJointInterface</hardwareInterface>
      <mechanicalReduction>1</mechanicalReduction>
    </actuator>
  </transmission>
  <gazebo reference="right_xarm_gripper_base_link">
    <selfCollide>false</selfCollide>
  </gazebo>
  <gazebo reference="right_left_outer_knuckle">
    <selfCollide>false</selfCollide>
  </gazebo>
  <gazebo reference="right_left_finger">
    <selfCollide>false</selfCollide>
  </gazebo>
  <gazebo reference="right_left_inner_knuckle">
    <selfCollide>false</selfCollide>
  </gazebo>
  <gazebo reference="right_right_outer_knuckle">
    <selfCollide>false</selfCollide>
  </gazebo>
  <gazebo reference="right_right_finger">
    <selfCollide>false</selfCollide>
  </gazebo>
  <gazebo reference="right_right_inner_knuckle">
    <selfCollide>false</selfCollide>
  </gazebo>
  <gazebo>
    <plugin filename="libgazebo_mimic_joint_plugin.so" name="right_left_finger_jointmimic_joint_plugin">
      <joint>right_drive_joint</joint>
      <mimicJoint>right_left_finger_joint</mimicJoint>
      <!-- if set to true, PID parameters from "/gazebo_ros_control/pid_gains/${mimic_joint}" are loaded -->
      <hasPID/>
      <multiplier>1.0</multiplier>
      <offset>0</offset>
      <sensitiveness>0.0</sensitiveness>
      <!-- if absolute difference between setpoint and process value is below this threshold, do nothing; 0.0 = disable [rad] -->
      <maxEffort>10.0</maxEffort>
    </plugin>
  </gazebo>
  <gazebo>
    <plugin filename="libgazebo_mimic_joint_plugin.so" name="right_left_inner_knuckle_jointmimic_joint_plugin">
      <joint>right_drive_joint</joint>
      <mimicJoint>right_left_inner_knuckle_joint</mimicJoint>
      <!-- if set to true, PID parameters from "/gazebo_ros_control/pid_gains/${mimic_joint}" are loaded -->
      <hasPID/>
      <multiplier>1.0</multiplier>
      <offset>0</offset>
      <sensitiveness>0.0</sensitiveness>
      <!-- if absolute difference between setpoint and process value is below this threshold, do nothing; 0.0 = disable [rad] -->
      <maxEffort>10.0</maxEffort>
    </plugin>
  </gazebo>
  <gazebo>
    <plugin filename="libgazebo_mimic_joint_plugin.so" name="right_right_outer_knuckle_jointmimic_joint_plugin">
      <joint>right_drive_joint</joint>
      <mimicJoint>right_right_outer_knuckle_joint</mimicJoint>
      <!-- if set to true, PID parameters from "/gazebo_ros_control/pid_gains/${mimic_joint}" are loaded -->
      <hasPID/>
      <multiplier>1.0</multiplier>
      <offset>0</offset>
      <sensitiveness>0.0</sensitiveness>
      <!-- if absolute difference between setpoint and process value is below this threshold, do nothing; 0.0 = disable [rad] -->
      <maxEffort>10.0</maxEffort>
    </plugin>
  </gazebo>
  <gazebo>
    <plugin filename="libgazebo_mimic_joint_plugin.so" name="right_right_finger_jointmimic_joint_plugin">
      <joint>right_drive_joint</joint>
      <mimicJoint>right_right_finger_joint</mimicJoint>
      <!-- if set to true, PID parameters from "/gazebo_ros_control/pid_gains/${mimic_joint}" are loaded -->
      <hasPID/>
      <multiplier>1.0</multiplier>
      <offset>0</offset>
      <sensitiveness>0.0</sensitiveness>
      <!-- if absolute difference between setpoint and process value is below this threshold, do nothing; 0.0 = disable [rad] -->
      <maxEffort>10.0</maxEffort>
    </plugin>
  </gazebo>
  <gazebo>
    <plugin filename="libgazebo_mimic_joint_plugin.so" name="right_right_inner_knuckle_jointmimic_joint_plugin">
      <joint>right_drive_joint</joint>
      <mimicJoint>right_right_inner_knuckle_joint</mimicJoint>
      <!-- if set to true, PID parameters from "/gazebo_ros_control/pid_gains/${mimic_joint}" are loaded -->
      <hasPID/>
      <multiplier>1.0</multiplier>
      <offset>0</offset>
      <sensitiveness>0.0</sensitiveness>
      <!-- if absolute difference between setpoint and process value is below this threshold, do nothing; 0.0 = disable [rad] -->
      <maxEffort>10.0</maxEffort>
    </plugin>
  </gazebo>
  <gazebo>
    <plugin filename="libgazebo_ros2_control.so" name="gazebo_ros2_control">
      <robot_sim_type>gazebo_ros2_control/GazeboSystem</robot_sim_type>
      <parameters>/home/yashas/dev_ws/install/xarm_controller/share/xarm_controller/config/xarm6_controllers.yaml</parameters>
    </plugin>
  </gazebo>
  <!-- Insert at the end of xarm_device_macro.xacro -->
  <!-- Insert at the beginning of xarm_device_macro.xacro -->
  <material name="left_Black">
    <color rgba="0.0 0.0 0.0 1.0"/>
  </material>
  <material name="left_Red">
    <color rgba="0.8 0.0 0.0 1.0"/>
  </material>
  <material name="left_White">
    <color rgba="1.0 1.0 1.0 1.0"/>
  </material>
  <material name="left_Silver">
    <color rgba="0.753 0.753 0.753 1.0"/>
  </material>
  <joint name="left_world_joint" type="fixed">
    <parent link="left_arm_mount"/>
    <child link="left_link_base"/>
    <origin rpy="0 0 0" xyz="0 0 0"/>
  </joint>
  <ros2_control name="left_uf_robot_hardware/UFRobotFakeSystemHardware" type="system">
    <hardware>
      <plugin>uf_robot_hardware/UFRobotFakeSystemHardware</plugin>
    </hardware>
    <joint name="left_joint1">
      <command_interface name="position">
        <param name="min">-6.283185307179586</param>
        <param name="max">6.283185307179586</param>
      </command_interface>
      <command_interface name="velocity">
        <param name="min">-3.14</param>
        <param name="max">3.14</param>
      </command_interface>
      <state_interface name="position"/>
      <state_interface name="velocity"/>
      <!-- <state_interface name="effort"/> -->
    </joint>
    <joint name="left_joint2">
      <command_interface name="position">
        <param name="min">-2.059</param>
        <param name="max">2.0944</param>
      </command_interface>
      <command_interface name="velocity">
        <param name="min">-3.14</param>
        <param name="max">3.14</param>
      </command_interface>
      <state_interface name="position"/>
      <state_interface name="velocity"/>
      <!-- <state_interface name="effort"/> -->
    </joint>
    <joint name="left_joint3">
      <command_interface name="position">
        <param name="min">-6.283185307179586</param>
        <param name="max">6.283185307179586</param>
      </command_interface>
      <command_interface name="velocity">
        <param name="min">-3.14</param>
        <param name="max">3.14</param>
      </command_interface>
      <state_interface name="position"/>
      <state_interface name="velocity"/>
      <!-- <state_interface name="effort"/> -->
    </joint>
    <joint name="left_joint4">
      <command_interface name="position">
        <param name="min">-0.19198</param>
        <param name="max">3.927</param>
      </command_interface>
      <command_interface name="velocity">
        <param name="min">-3.14</param>
        <param name="max">3.14</param>
      </command_interface>
      <state_interface name="position"/>
      <state_interface name="velocity"/>
      <!-- <state_interface name="effort"/> -->
    </joint>
    <joint name="left_joint5">
      <command_interface name="position">
        <param name="min">-6.283185307179586</param>
        <param name="max">6.283185307179586</param>
      </command_interface>
      <command_interface name="velocity">
        <param name="min">-3.14</param>
        <param name="max">3.14</param>
      </command_interface>
      <state_interface name="position"/>
      <state_interface name="velocity"/>
      <!-- <state_interface name="effort"/> -->
    </joint>
    <joint name="left_joint6">
      <command_interface name="position">
        <param name="min">-1.69297</param>
        <param name="max">3.141592653589793</param>
      </command_interface>
      <command_interface name="velocity">
        <param name="min">-3.14</param>
        <param name="max">3.14</param>
      </command_interface>
      <state_interface name="position"/>
      <state_interface name="velocity"/>
      <!-- <state_interface name="effort"/> -->
    </joint>
    <joint name="left_joint7">
      <command_interface name="position">
        <param name="min">-6.283185307179586</param>
        <param name="max">6.283185307179586</param>
      </command_interface>
      <command_interface name="velocity">
        <param name="min">-3.14</param>
        <param name="max">3.14</param>
      </command_interface>
      <state_interface name="position"/>
      <state_interface name="velocity"/>
      <!-- <state_interface name="effort"/> -->
    </joint>
  </ros2_control>
  <link name="left_link_base">
    <inertial>
      <origin rpy="0 0 0" xyz="-0.021131 -0.0016302 0.056488"/>
      <mass value="0.88556"/>
      <inertia ixx="0.0030595" ixy="0.00012259" ixz="-0.00062705" iyy="0.0037783" iyz="0.00027023" izz="0.0020125"/>
    </inertial>
    <visual>
      <geometry>
        <mesh filename="package://xarm_description/meshes/xarm7/visual/link_base.stl"/>
      </geometry>
      <origin rpy="0 0 0" xyz="0 0 0"/>
      <material name="left_White"/>
    </visual>
    <collision>
      <geometry>
        <mesh filename="package://xarm_description/meshes/xarm7/visual/link_base.stl"/>
      </geometry>
      <origin rpy="0 0 0" xyz="0 0 0"/>
    </collision>
  </link>
  <link name="left_link1">
    <inertial>
      <origin rpy="0 0 0" xyz="-0.0002 0.02905 -0.01233"/>
      <mass value="2.382"/>
      <inertia ixx="0.0056905" ixy="-1.579e-05" ixz="5.125e-06" iyy="0.0049566" iyz="-0.000873378" izz="0.003316654"/>
    </inertial>
    <visual>
      <geometry>
        <mesh filename="package://xarm_description/meshes/xarm7/visual/link1.stl"/>
      </geometry>
      <origin rpy="0 0 0" xyz="0 0 0"/>
      <material name="left_White"/>
    </visual>
    <collision>
      <geometry>
        <mesh filename="package://xarm_description/meshes/xarm7/visual/link1.stl"/>
      </geometry>
      <origin rpy="0 0 0" xyz="0 0 0"/>
    </collision>
  </link>
  <joint name="left_joint1" type="revolute">
    <origin rpy="0 0 0" xyz="0 0 0.267"/>
    <parent link="left_link_base"/>
    <child link="left_link1"/>
    <axis xyz="0 0 1"/>
    <limit effort="50" lower="-6.283185307179586" upper="6.283185307179586" velocity="3.14"/>
    <dynamics damping="10" friction="1"/>
  </joint>
  <link name="left_link2">
    <inertial>
      <origin rpy="0 0 0" xyz="0.00022 -0.12856 0.01735"/>
      <mass value="1.869"/>
      <inertia ixx="0.0095989" ixy="1.541e-06" ixz="5.56e-06" iyy="0.00382472" iyz="-0.00317156" izz="0.007565669"/>
    </inertial>
    <visual>
      <geometry>
        <mesh filename="package://xarm_description/meshes/xarm7/visual/link2.stl"/>
      </geometry>
      <origin rpy="0 0 0" xyz="0 0 0"/>
      <material name="left_White"/>
    </visual>
    <collision>
      <geometry>
        <mesh filename="package://xarm_description/meshes/xarm7/visual/link2.stl"/>
      </geometry>
      <origin rpy="0 0 0" xyz="0 0 0"/>
    </collision>
  </link>
  <joint name="left_joint2" type="revolute">
    <origin rpy="-1.5708 0 0" xyz="0 0 0"/>
    <parent link="left_link1"/>
    <child link="left_link2"/>
    <axis xyz="0 0 1"/>
    <limit effort="50" lower="-2.059" upper="2.0944" velocity="3.14"/>
    <dynamics damping="10" friction="1"/>
  </joint>
  <link name="left_link3">
    <inertial>
      <origin rpy="0 0 0" xyz="0.0466 -0.02463 -0.00768"/>
      <mass value="1.6383"/>
      <inertia ixx="0.00310955" ixy="0.00030837" ixz="-0.00058453" iyy="0.00264483" iyz="0.000338893" izz="0.0026624"/>
    </inertial>
    <visual>
      <geometry>
        <mesh filename="package://xarm_description/meshes/xarm7/visual/link3.stl"/>
      </geometry>
      <origin rpy="0 0 0" xyz="0 0 0"/>
      <material name="left_White"/>
    </visual>
    <collision>
      <geometry>
        <mesh filename="package://xarm_description/meshes/xarm7/visual/link3.stl"/>
      </geometry>
      <origin rpy="0 0 0" xyz="0 0 0"/>
    </collision>
  </link>
  <joint name="left_joint3" type="revolute">
    <origin rpy="1.5708 0 0" xyz="0 -0.293 0"/>
    <parent link="left_link2"/>
    <child link="left_link3"/>
    <axis xyz="0 0 1"/>
    <limit effort="30" lower="-6.283185307179586" upper="6.283185307179586" velocity="3.14"/>
    <dynamics damping="5" friction="1"/>
  </joint>
  <link name="left_link4">
    <inertial>
      <origin rpy="0 0 0" xyz="0.07047 -0.11575 0.012"/>
      <mass value="1.7269"/>
      <inertia ixx="0.005889" ixy="0.00137112" ixz="0.00088143" iyy="0.00359703" iyz="-0.001762155" izz="0.00543244"/>
    </inertial>
    <visual>
      <geometry>
        <mesh filename="package://xarm_description/meshes/xarm7/visual/link4.stl"/>
      </geometry>
      <origin rpy="0 0 0" xyz="0 0 0"/>
      <material name="left_White"/>
    </visual>
    <collision>
      <geometry>
        <mesh filename="package://xarm_description/meshes/xarm7/visual/link4.stl"/>
      </geometry>
      <origin rpy="0 0 0" xyz="0 0 0"/>
    </collision>
  </link>
  <joint name="left_joint4" type="revolute">
    <origin rpy="1.5708 0 0" xyz="0.0525 0 0"/>
    <parent link="left_link3"/>
    <child link="left_link4"/>
    <axis xyz="0 0 1"/>
    <limit effort="30" lower="-0.19198" upper="3.927" velocity="3.14"/>
    <dynamics damping="5" friction="1"/>
  </joint>
  <link name="left_link5">
    <inertial>
      <origin rpy="0 0 0" xyz="-0.00032 0.01604 -0.026"/>
      <mass value="1.3203"/>
      <inertia ixx="0.00534665" ixy="1.5117e-05" ixz="-3.69e-07" iyy="0.0049779" iyz="-0.00022132" izz="0.0013624"/>
    </inertial>
    <visual>
      <geometry>
        <mesh filename="package://xarm_description/meshes/xarm7/visual/link5.stl"/>
      </geometry>
      <origin rpy="0 0 0" xyz="0 0 0"/>
      <material name="left_White"/>
    </visual>
    <collision>
      <geometry>
        <mesh filename="package://xarm_description/meshes/xarm7/visual/link5.stl"/>
      </geometry>
      <origin rpy="0 0 0" xyz="0 0 0"/>
    </collision>
  </link>
  <joint name="left_joint5" type="revolute">
    <origin rpy="1.5708 0 0" xyz="0.0775 -0.3425 0"/>
    <parent link="left_link4"/>
    <child link="left_link5"/>
    <axis xyz="0 0 1"/>
    <limit effort="30" lower="-6.283185307179586" upper="6.283185307179586" velocity="3.14"/>
    <dynamics damping="5" friction="1"/>
  </joint>
  <link name="left_link6">
    <inertial>
      <origin rpy="0 0 0" xyz="0.06469 0.03278 0.02141"/>
      <mass value="1.325"/>
      <inertia ixx="0.0014745" ixy="-0.000488" ixz="0.0002953" iyy="0.0019037" iyz="0.00014749" izz="0.0023652"/>
    </inertial>
    <visual>
      <geometry>
        <mesh filename="package://xarm_description/meshes/xarm7/visual/link6.stl"/>
      </geometry>
      <origin rpy="0 0 0" xyz="0 0 0"/>
      <material name="left_White"/>
    </visual>
    <collision>
      <geometry>
        <mesh filename="package://xarm_description/meshes/xarm7/visual/link6.stl"/>
      </geometry>
      <origin rpy="0 0 0" xyz="0 0 0"/>
    </collision>
  </link>
  <joint name="left_joint6" type="revolute">
    <origin rpy="1.5708 0 0" xyz="0 0 0"/>
    <parent link="left_link5"/>
    <child link="left_link6"/>
    <axis xyz="0 0 1"/>
    <limit effort="20" lower="-1.69297" upper="3.141592653589793" velocity="3.14"/>
    <dynamics damping="2" friction="1"/>
  </joint>
  <link name="left_link7">
    <inertial>
      <origin rpy="0 0 0" xyz="0 -0.00677 -0.01098"/>
      <mass value="0.17"/>
      <inertia ixx="9.3e-05" ixy="-0.0" ixz="-0.0" iyy="5.87e-05" iyz="-3.6e-06" izz="0.000132"/>
    </inertial>
    <visual>
      <geometry>
        <mesh filename="package://xarm_description/meshes/xarm7/visual/link7.stl"/>
      </geometry>
      <origin rpy="0 0 0" xyz="0 0 0"/>
      <material name="left_Silver"/>
    </visual>
    <collision>
      <geometry>
        <mesh filename="package://xarm_description/meshes/end_tool/collision/end_tool.stl"/>
      </geometry>
      <origin rpy="0 0 0" xyz="0 0 0"/>
    </collision>
  </link>
  <joint name="left_joint7" type="revolute">
    <origin rpy="-1.5708 0 0" xyz="0.076 0.097 0"/>
    <parent link="left_link6"/>
    <child link="left_link7"/>
    <axis xyz="0 0 1"/>
    <limit effort="20" lower="-6.283185307179586" upper="6.283185307179586" velocity="3.14"/>
    <dynamics damping="2" friction="1"/>
  </joint>
  <!-- <link name="${prefix}link_eef" />
    <joint name="${prefix}joint_eef" type="fixed">
      <origin xyz="0 0 0" rpy="0 0 0" />
      <parent link="${prefix}link7" />
      <child link="${prefix}link_eef" />
    </joint> -->
  <transmission name="left_tran1">
    <type>transmission_interface/SimpleTransmission</type>
    <joint name="left_joint1">
      <hardwareInterface>hardware_interface/PositionJointInterface</hardwareInterface>
    </joint>
    <actuator name="left_motor1">
      <hardwareInterface>hardware_interface/PositionJointInterface</hardwareInterface>
      <mechanicalReduction>100</mechanicalReduction>
    </actuator>
  </transmission>
  <transmission name="left_tran2">
    <type>transmission_interface/SimpleTransmission</type>
    <joint name="left_joint2">
      <hardwareInterface>hardware_interface/PositionJointInterface</hardwareInterface>
    </joint>
    <actuator name="left_motor2">
      <hardwareInterface>hardware_interface/PositionJointInterface</hardwareInterface>
      <mechanicalReduction>100</mechanicalReduction>
    </actuator>
  </transmission>
  <transmission name="left_tran3">
    <type>transmission_interface/SimpleTransmission</type>
    <joint name="left_joint3">
      <hardwareInterface>hardware_interface/PositionJointInterface</hardwareInterface>
    </joint>
    <actuator name="left_motor3">
      <hardwareInterface>hardware_interface/PositionJointInterface</hardwareInterface>
      <mechanicalReduction>100</mechanicalReduction>
    </actuator>
  </transmission>
  <transmission name="left_tran4">
    <type>transmission_interface/SimpleTransmission</type>
    <joint name="left_joint4">
      <hardwareInterface>hardware_interface/PositionJointInterface</hardwareInterface>
    </joint>
    <actuator name="left_motor4">
      <hardwareInterface>hardware_interface/PositionJointInterface</hardwareInterface>
      <mechanicalReduction>100</mechanicalReduction>
    </actuator>
  </transmission>
  <transmission name="left_tran5">
    <type>transmission_interface/SimpleTransmission</type>
    <joint name="left_joint5">
      <hardwareInterface>hardware_interface/PositionJointInterface</hardwareInterface>
    </joint>
    <actuator name="left_motor5">
      <hardwareInterface>hardware_interface/PositionJointInterface</hardwareInterface>
      <mechanicalReduction>100</mechanicalReduction>
    </actuator>
  </transmission>
  <transmission name="left_tran6">
    <type>transmission_interface/SimpleTransmission</type>
    <joint name="left_joint6">
      <hardwareInterface>hardware_interface/PositionJointInterface</hardwareInterface>
    </joint>
    <actuator name="left_motor6">
      <hardwareInterface>hardware_interface/PositionJointInterface</hardwareInterface>
      <mechanicalReduction>100</mechanicalReduction>
    </actuator>
  </transmission>
  <transmission name="left_tran7">
    <type>transmission_interface/SimpleTransmission</type>
    <joint name="left_joint7">
      <hardwareInterface>hardware_interface/PositionJointInterface</hardwareInterface>
    </joint>
    <actuator name="left_motor7">
      <hardwareInterface>hardware_interface/PositionJointInterface</hardwareInterface>
      <mechanicalReduction>100</mechanicalReduction>
    </actuator>
  </transmission>
  <gazebo reference="left_link_base">
    <selfCollide>true</selfCollide>
  </gazebo>
  <gazebo reference="left_link1">
    <selfCollide>true</selfCollide>
  </gazebo>
  <gazebo reference="left_link2">
    <selfCollide>true</selfCollide>
  </gazebo>
  <gazebo reference="left_link3">
    <selfCollide>true</selfCollide>
  </gazebo>
  <gazebo reference="left_link4">
    <selfCollide>true</selfCollide>
  </gazebo>
  <gazebo reference="left_link5">
    <selfCollide>true</selfCollide>
  </gazebo>
  <gazebo reference="left_link6">
    <selfCollide>true</selfCollide>
  </gazebo>
  <gazebo reference="left_link7">
    <selfCollide>true</selfCollide>
  </gazebo>
  <link name="left_link_eef"/>
  <joint name="left_joint_eef" type="fixed">
    <origin rpy="0 0 0" xyz="0 0 0"/>
    <parent link="left_link7"/>
    <child link="left_link_eef"/>
  </joint>
  <ros2_control name="left_XArmGripperSystem" type="system">
    <hardware>
      <plugin>uf_robot_hardware/UFRobotFakeSystemHardware</plugin>
    </hardware>
    <joint name="left_drive_joint">
      <command_interface name="position">
        </command_interface>
      <command_interface name="velocity">
        <param name="min">-3.14</param>
        <param name="max">3.14</param>
      </command_interface>
      <state_interface name="position"/>
      <state_interface name="velocity"/>
      <!-- <state_interface name="effort"/> -->
    </joint>
  </ros2_control>
  <joint name="left_gripper_fix" type="fixed">
    <parent link="left_link_eef"/>
    <child link="left_xarm_gripper_base_link"/>
    <origin rpy="0 0 0" xyz="0 0 0"/>
  </joint>
  <link name="left_xarm_gripper_base_link">
    <inertial>
      <origin rpy="0 0 0" xyz="-0.00065489 -0.0018497 0.048028"/>
      <mass value="0.54156"/>
      <inertia ixx="0.00047106" ixy="3.9292E-07" ixz="2.6537E-06" iyy="0.00033072" iyz="-1.0975E-05" izz="0.00025642"/>
    </inertial>
    <visual>
      <geometry>
        <mesh filename="package://xarm_description/meshes/gripper/xarm/base_link.stl"/>
      </geometry>
      <origin rpy="0 0 0" xyz="0 0 0"/>
      <material name="left_White"/>
    </visual>
    <collision>
      <geometry>
        <mesh filename="package://xarm_description/meshes/gripper/xarm/base_link.stl"/>
      </geometry>
      <origin rpy="0 0 0" xyz="0 0 0"/>
    </collision>
  </link>
  <link name="left_left_outer_knuckle">
    <inertial>
      <origin rpy="0 0 0" xyz="2.9948E-14 0.021559 0.015181"/>
      <mass value="0.033618"/>
      <inertia ixx="1.9111E-05" ixy="-1.8803E-17" ixz="-1.1002E-17" iyy="6.6256E-06" iyz="-7.3008E-06" izz="1.3185E-05"/>
    </inertial>
    <visual>
      <geometry>
        <mesh filename="package://xarm_description/meshes/gripper/xarm/left_outer_knuckle.stl"/>
      </geometry>
      <origin rpy="0 0 0" xyz="0 0 0"/>
      <material name="left_Silver"/>
    </visual>
    <collision>
      <geometry>
        <mesh filename="package://xarm_description/meshes/gripper/xarm/left_outer_knuckle.stl"/>
      </geometry>
      <origin rpy="0 0 0" xyz="0 0 0"/>
    </collision>
  </link>
  <joint name="left_drive_joint" type="revolute">
    <origin rpy="0 0 0" xyz="0 0.035 0.059098"/>
    <parent link="left_xarm_gripper_base_link"/>
    <child link="left_left_outer_knuckle"/>
    <axis xyz="1 0 0"/>
    <limit effort="50" lower="0" upper="0.85" velocity="2"/>
  </joint>
  <link name="left_left_finger">
    <inertial>
      <origin rpy="0 0 0" xyz="-2.4536E-14 -0.016413 0.029258"/>
      <mass value="0.048304"/>
      <inertia ixx="1.7493E-05" ixy="-4.2156E-19" ixz="6.9164E-18" iyy="1.7225E-05" iyz="4.6433E-06" izz="5.1466E-06"/>
    </inertial>
    <visual>
      <geometry>
        <mesh filename="package://xarm_description/meshes/gripper/xarm/left_finger.stl"/>
      </geometry>
      <origin rpy="0 0 0" xyz="0 0 0"/>
      <material name="left_Silver"/>
    </visual>
    <collision>
      <geometry>
        <mesh filename="package://xarm_description/meshes/gripper/xarm/left_finger.stl"/>
      </geometry>
      <origin rpy="0 0 0" xyz="0 0 0"/>
    </collision>
  </link>
  <joint name="left_left_finger_joint" type="revolute">
    <origin rpy="0 0 0" xyz="0 0.035465 0.042039"/>
    <parent link="left_left_outer_knuckle"/>
    <child link="left_left_finger"/>
    <axis xyz="-1 0 0"/>
    <limit effort="50" lower="0" upper="0.85" velocity="2"/>
    <mimic joint="left_drive_joint" multiplier="1" offset="0"/>
  </joint>
  <link name="left_left_inner_knuckle">
    <inertial>
      <origin rpy="0 0 0" xyz="1.86600784687907E-06 0.0220467847633621 0.0261334672830885"/>
      <mass value="0.0230125781256706"/>
      <inertia ixx="6.09490024271906E-06" ixy="6.06651326160071E-11" ixz="7.19102670500635E-11" iyy="6.01955084375188E-06" iyz="-2.75316812991721E-06" izz="5.07862004479903E-06"/>
    </inertial>
    <visual>
      <geometry>
        <mesh filename="package://xarm_description/meshes/gripper/xarm/left_inner_knuckle.stl"/>
      </geometry>
      <origin rpy="0 0 0" xyz="0 0 0"/>
      <material name="left_Silver"/>
    </visual>
    <collision>
      <geometry>
        <mesh filename="package://xarm_description/meshes/gripper/xarm/left_inner_knuckle.stl"/>
      </geometry>
      <origin rpy="0 0 0" xyz="0 0 0"/>
    </collision>
  </link>
  <joint name="left_left_inner_knuckle_joint" type="revolute">
    <origin rpy="0 0 0" xyz="0 0.02 0.074098"/>
    <parent link="left_xarm_gripper_base_link"/>
    <child link="left_left_inner_knuckle"/>
    <axis xyz="1 0 0"/>
    <limit effort="50" lower="0" upper="0.85" velocity="2"/>
    <mimic joint="left_drive_joint" multiplier="1" offset="0"/>
  </joint>
  <link name="left_right_outer_knuckle">
    <inertial>
      <origin rpy="0 0 0" xyz="-3.1669E-14 -0.021559 0.015181"/>
      <mass value="0.033618"/>
      <inertia ixx="1.9111E-05" ixy="-1.8789E-17" ixz="1.0986E-17" iyy="6.6256E-06" iyz="7.3008E-06" izz="1.3185E-05"/>
    </inertial>
    <visual>
      <geometry>
        <mesh filename="package://xarm_description/meshes/gripper/xarm/right_outer_knuckle.stl"/>
      </geometry>
      <origin rpy="0 0 0" xyz="0 0 0"/>
      <material name="left_Silver"/>
    </visual>
    <collision>
      <geometry>
        <mesh filename="package://xarm_description/meshes/gripper/xarm/right_outer_knuckle.stl"/>
      </geometry>
      <origin rpy="0 0 0" xyz="0 0 0"/>
    </collision>
  </link>
  <joint name="left_right_outer_knuckle_joint" type="revolute">
    <origin rpy="0 0 0" xyz="0 -0.035 0.059098"/>
    <parent link="left_xarm_gripper_base_link"/>
    <child link="left_right_outer_knuckle"/>
    <axis xyz="-1 0 0"/>
    <limit effort="50" lower="0" upper="0.85" velocity="2"/>
    <mimic joint="left_drive_joint" multiplier="1" offset="0"/>
  </joint>
  <link name="left_right_finger">
    <inertial>
      <origin rpy="0 0 0" xyz="2.5618E-14 0.016413 0.029258"/>
      <mass value="0.048304"/>
      <inertia ixx="1.7493E-05" ixy="-5.0014E-19" ixz="-7.5079E-18" iyy="1.7225E-05" iyz="-4.6435E-06" izz="5.1466E-06"/>
    </inertial>
    <visual>
      <geometry>
        <mesh filename="package://xarm_description/meshes/gripper/xarm/right_finger.stl"/>
      </geometry>
      <origin rpy="0 0 0" xyz="0 0 0"/>
      <material name="left_Silver"/>
    </visual>
    <collision>
      <geometry>
        <mesh filename="package://xarm_description/meshes/gripper/xarm/right_finger.stl"/>
      </geometry>
      <origin rpy="0 0 0" xyz="0 0 0"/>
    </collision>
  </link>
  <joint name="left_right_finger_joint" type="revolute">
    <origin rpy="0 0 0" xyz="0 -0.035465 0.042039"/>
    <parent link="left_right_outer_knuckle"/>
    <child link="left_right_finger"/>
    <axis xyz="1 0 0"/>
    <limit effort="50" lower="0" upper="0.85" velocity="2"/>
    <mimic joint="left_drive_joint" multiplier="1" offset="0"/>
  </joint>
  <link name="left_right_inner_knuckle">
    <inertial>
      <origin rpy="0 0 0" xyz="1.866E-06 -0.022047 0.026133"/>
      <mass value="0.023013"/>
      <inertia ixx="6.0949E-06" ixy="-6.0665E-11" ixz="7.191E-11" iyy="6.0197E-06" iyz="2.7531E-06" izz="5.0784E-06"/>
    </inertial>
    <visual>
      <geometry>
        <mesh filename="package://xarm_description/meshes/gripper/xarm/right_inner_knuckle.stl"/>
      </geometry>
      <origin rpy="0 0 0" xyz="0 0 0"/>
      <material name="left_Silver"/>
    </visual>
    <collision>
      <geometry>
        <mesh filename="package://xarm_description/meshes/gripper/xarm/right_inner_knuckle.stl"/>
      </geometry>
      <origin rpy="0 0 0" xyz="0 0 0"/>
    </collision>
  </link>
  <joint name="left_right_inner_knuckle_joint" type="revolute">
    <origin rpy="0 0 0" xyz="0 -0.02 0.074098"/>
    <parent link="left_xarm_gripper_base_link"/>
    <child link="left_right_inner_knuckle"/>
    <axis xyz="-1 0 0"/>
    <limit effort="50" lower="0" upper="0.85" velocity="2"/>
    <mimic joint="left_drive_joint" multiplier="1" offset="0"/>
  </joint>
  <link name="left_link_tcp"/>
  <joint name="left_joint_tcp" type="fixed">
    <origin rpy="0 0 0" xyz="0 0 0.172"/>
    <parent link="left_xarm_gripper_base_link"/>
    <child link="left_link_tcp"/>
  </joint>
  <transmission name="left_drive_joint_trans">
    <type>transmission_interface/SimpleTransmission</type>
    <joint name="left_drive_joint">
      <hardwareInterface>hardware_interface/PositionJointInterface</hardwareInterface>
    </joint>
    <actuator name="left_drive_joint_motor">
      <hardwareInterface>hardware_interface/PositionJointInterface</hardwareInterface>
      <mechanicalReduction>1</mechanicalReduction>
    </actuator>
  </transmission>
  <gazebo reference="left_xarm_gripper_base_link">
    <selfCollide>false</selfCollide>
  </gazebo>
  <gazebo reference="left_left_outer_knuckle">
    <selfCollide>false</selfCollide>
  </gazebo>
  <gazebo reference="left_left_finger">
    <selfCollide>false</selfCollide>
  </gazebo>
  <gazebo reference="left_left_inner_knuckle">
    <selfCollide>false</selfCollide>
  </gazebo>
  <gazebo reference="left_right_outer_knuckle">
    <selfCollide>false</selfCollide>
  </gazebo>
  <gazebo reference="left_right_finger">
    <selfCollide>false</selfCollide>
  </gazebo>
  <gazebo reference="left_right_inner_knuckle">
    <selfCollide>false</selfCollide>
  </gazebo>
  <gazebo>
    <plugin filename="libgazebo_mimic_joint_plugin.so" name="left_left_finger_jointmimic_joint_plugin">
      <joint>left_drive_joint</joint>
      <mimicJoint>left_left_finger_joint</mimicJoint>
      <!-- if set to true, PID parameters from "/gazebo_ros_control/pid_gains/${mimic_joint}" are loaded -->
      <hasPID/>
      <multiplier>1.0</multiplier>
      <offset>0</offset>
      <sensitiveness>0.0</sensitiveness>
      <!-- if absolute difference between setpoint and process value is below this threshold, do nothing; 0.0 = disable [rad] -->
      <maxEffort>10.0</maxEffort>
    </plugin>
  </gazebo>
  <gazebo>
    <plugin filename="libgazebo_mimic_joint_plugin.so" name="left_left_inner_knuckle_jointmimic_joint_plugin">
      <joint>left_drive_joint</joint>
      <mimicJoint>left_left_inner_knuckle_joint</mimicJoint>
      <!-- if set to true, PID parameters from "/gazebo_ros_control/pid_gains/${mimic_joint}" are loaded -->
      <hasPID/>
      <multiplier>1.0</multiplier>
      <offset>0</offset>
      <sensitiveness>0.0</sensitiveness>
      <!-- if absolute difference between setpoint and process value is below this threshold, do nothing; 0.0 = disable [rad] -->
      <maxEffort>10.0</maxEffort>
    </plugin>
  </gazebo>
  <gazebo>
    <plugin filename="libgazebo_mimic_joint_plugin.so" name="left_right_outer_knuckle_jointmimic_joint_plugin">
      <joint>left_drive_joint</joint>
      <mimicJoint>left_right_outer_knuckle_joint</mimicJoint>
      <!-- if set to true, PID parameters from "/gazebo_ros_control/pid_gains/${mimic_joint}" are loaded -->
      <hasPID/>
      <multiplier>1.0</multiplier>
      <offset>0</offset>
      <sensitiveness>0.0</sensitiveness>
      <!-- if absolute difference between setpoint and process value is below this threshold, do nothing; 0.0 = disable [rad] -->
      <maxEffort>10.0</maxEffort>
    </plugin>
  </gazebo>
  <gazebo>
    <plugin filename="libgazebo_mimic_joint_plugin.so" name="left_right_finger_jointmimic_joint_plugin">
      <joint>left_drive_joint</joint>
      <mimicJoint>left_right_finger_joint</mimicJoint>
      <!-- if set to true, PID parameters from "/gazebo_ros_control/pid_gains/${mimic_joint}" are loaded -->
      <hasPID/>
      <multiplier>1.0</multiplier>
      <offset>0</offset>
      <sensitiveness>0.0</sensitiveness>
      <!-- if absolute difference between setpoint and process value is below this threshold, do nothing; 0.0 = disable [rad] -->
      <maxEffort>10.0</maxEffort>
    </plugin>
  </gazebo>
  <gazebo>
    <plugin filename="libgazebo_mimic_joint_plugin.so" name="left_right_inner_knuckle_jointmimic_joint_plugin">
      <joint>left_drive_joint</joint>
      <mimicJoint>left_right_inner_knuckle_joint</mimicJoint>
      <!-- if set to true, PID parameters from "/gazebo_ros_control/pid_gains/${mimic_joint}" are loaded -->
      <hasPID/>
      <multiplier>1.0</multiplier>
      <offset>0</offset>
      <sensitiveness>0.0</sensitiveness>
      <!-- if absolute difference between setpoint and process value is below this threshold, do nothing; 0.0 = disable [rad] -->
      <maxEffort>10.0</maxEffort>
    </plugin>
  </gazebo>
  <!-- Insert at the end of xarm_device_macro.xacro -->
</robot>
