<?xml version="1.0" ?>
<!-- =================================================================================== -->
<!-- |    This document was autogenerated by xacro from alfred_base_descr.urdf.xacro   | -->
<!-- |    EDITING THIS FILE BY HAND IS NOT RECOMMENDED                                 | -->
<!-- =================================================================================== -->
<robot name="alfred_base_descr">
  <!-- <xacro:alfred_base base_frame="world" base_pos_x="0.0" base_pos_y="0.0" base_pos_z="0.0" base_roll="0.0" base_pitch="0.0" base_yaw="0.0" r="0.8" g="0.8" b="0.8" a="1.0" /> -->
  <link name="world"/>
  <link name="base_center"/>
  <joint name="base_parent_joint" type="fixed">
    <parent link="world"/>
    <child link="base_center"/>
    <origin rpy="0 0 0" xyz="0 0 0"/>
  </joint>
  <link name="alfred_base_link">
    <visual>
      <origin rpy="0.0 0.0 0.0" xyz="0.0 0.0 0.0"/>
      <geometry>
        <mesh filename="package://dim_cpp/urdf/meshes/base-visual.stl" scale="0.001 0.001 0.001"/>
      </geometry>
      <material name="mat">
        <color rgba="0.8 0.8 0.8 1.0"/>
      </material>
    </visual>
    <collision>
      <origin rpy="0.0 0.0 0.0" xyz="0.0 0.0 0.0"/>
      <geometry>
        <mesh filename="package://dim_cpp/urdf/meshes/base-collision.stl" scale="0.001 0.001 0.001"/>
      </geometry>
      <material name="mat">
        <color rgba="0.8 0.8 0.8 1.0"/>
      </material>
    </collision>
    <inertial>
      <mass value="45"/>
      <inertia ixx="12.732327" ixy="0" ixz="0" iyy="12.513553" iyz="0" izz="1.8057749"/>
      <origin rpy="0 0 0" xyz=".225 -.2125 .9125"/>
    </inertial>
  </link>
  <joint name="base_center_joint" type="fixed">
    <parent link="base_center"/>
    <child link="alfred_base_link"/>
    <origin rpy="0 0 0" xyz="-.225 .2125 .1232"/>
  </joint>
  <link name="botwheel_left">
    <visual>
      <origin rpy="0 0 0" xyz="0 0 0"/>
      <geometry>
        <mesh filename="package://dim_cpp/urdf/meshes/botwheel-visual.stl" scale="0.001 0.001 0.001"/>
      </geometry>
      <material name="mat">
        <color rgba="0.8 0.8 0.8 1.0"/>
      </material>
    </visual>
    <collision>
      <origin rpy="0 0 0" xyz="0 0 0"/>
      <geometry>
        <mesh filename="package://dim_cpp/urdf/meshes/botwheel-collision.stl" scale="0.001 0.001 0.001"/>
      </geometry>
      <material name="mat">
        <color rgba="0.8 0.8 0.8 1.0"/>
      </material>
    </collision>
    <inertial>
      <mass value="2.2"/>
      <inertia ixx="0.006434956" ixy="0" ixz="0" iyy="0.01074723" iyz="0" izz="0.006435717"/>
    </inertial>
  </link>
  <joint name="left_wheel_joint" type="continuous">
    <parent link="alfred_base_link"/>
    <child link="botwheel_left"/>
    <origin rpy="0 0 -1.5707" xyz="-0.0561 -0.395 -0.0375"/>
    <axis xyz="0 1 0"/>
  </joint>
  <link name="botwheel_right">
    <visual>
      <origin rpy="0 0 0" xyz="0 0 0"/>
      <geometry>
        <mesh filename="package://dim_cpp/urdf/meshes/botwheel-visual.stl" scale="0.001 0.001 0.001"/>
      </geometry>
      <material name="mat">
        <color rgba="0.8 0.8 0.8 1.0"/>
      </material>
    </visual>
    <collision>
      <origin rpy="0 0 0" xyz="0 0 0"/>
      <geometry>
        <mesh filename="package://dim_cpp/urdf/meshes/botwheel-collision.stl" scale="0.001 0.001 0.001"/>
      </geometry>
      <material name="mat">
        <color rgba="0.8 0.8 0.8 1.0"/>
      </material>
    </collision>
    <inertial>
      <mass value="2.2"/>
      <inertia ixx="0.006434956" ixy="0" ixz="0" iyy="0.01074723" iyz="0" izz="0.006435717"/>
    </inertial>
  </link>
  <joint name="right_wheel_joint" type="continuous">
    <parent link="alfred_base_link"/>
    <child link="botwheel_right"/>
    <origin rpy="0 0 1.5707" xyz="0.5061 -0.395 -0.0375"/>
    <axis xyz="0 1 0"/>
  </joint>
  <link name="pillar_platform">
    <visual>
      <origin rpy="0 0 0" xyz="0 0 0"/>
      <geometry>
        <mesh filename="package://dim_cpp/urdf/meshes/pillarplatform-visual.stl" scale="0.001 0.001 0.001"/>
      </geometry>
      <material name="mat">
        <color rgba="0.8 0.8 0.8 1.0"/>
      </material>
    </visual>
    <collision>
      <origin rpy="0 0 0" xyz="0 0 0"/>
      <geometry>
        <mesh filename="package://dim_cpp/urdf/meshes/pillarplatform-collision.stl" scale="0.001 0.001 0.001"/>
      </geometry>
      <material name="mat">
        <color rgba="0.8 0.8 0.8 1.0"/>
      </material>
    </collision>
    <inertial>
      <mass value="1.5"/>
      <inertia ixx="0.008729344" ixy="0" ixz="0" iyy="0.0085796565" iyz="0" izz="0.01050275"/>
      <origin rpy="0 0 0" xyz=".225 -.365 1.41"/>
    </inertial>
  </link>
  <joint name="pillar_platform_joint" type="prismatic">
    <parent link="alfred_base_link"/>
    <child link="pillar_platform"/>
    <origin rpy="0 0 0" xyz="0 0 0"/>
    <axis xyz="0 0 1"/>
    <limit effort="100" lower="-0.83" upper="0.0" velocity="0.1"/>
  </joint>
  <link name="tilt_base">
    <visual>
      <origin rpy="0 0 0" xyz="-.225 .365 -1.645"/>
      <geometry>
        <mesh filename="package://dim_cpp/urdf/meshes/tiltbase-visual.stl" scale="0.001 0.001 0.001"/>
      </geometry>
      <material name="mat">
        <color rgba="0.8 0.8 0.8 1.0"/>
      </material>
    </visual>
    <collision>
      <origin rpy="0 0 0" xyz="-.225 .365 -1.645"/>
      <geometry>
        <mesh filename="package://dim_cpp/urdf/meshes/tiltbase-collision.stl" scale="0.001 0.001 0.001"/>
      </geometry>
      <material name="mat">
        <color rgba="0.8 0.8 0.8 1.0"/>
      </material>
    </collision>
    <inertial>
      <mass value=".15"/>
      <inertia ixx="8.479636e-05" ixy="0" ixz="0" iyy="0.00013581244" iyz="0" izz="0.0001717679"/>
    </inertial>
  </link>
  <joint name="tilt_base_joint" type="revolute">
    <parent link="alfred_base_link"/>
    <child link="tilt_base"/>
    <origin rpy="0 0 0" xyz=".225 -.365 1.645"/>
    <axis xyz="0 0 1"/>
    <limit effort="100" lower="-1.57" upper="1.57" velocity="0.1"/>
  </joint>
  <link name="camera_holder">
    <visual>
      <origin rpy="0 0 0" xyz="-.225 .365 -1.659"/>
      <geometry>
        <mesh filename="package://dim_cpp/urdf/meshes/cameraholder-visual.stl" scale="0.001 0.001 0.001"/>
      </geometry>
      <material name="mat">
        <color rgba="0.8 0.8 0.8 1.0"/>
      </material>
    </visual>
    <collision>
      <origin rpy="0 0 0" xyz="-.225 .365 -1.659"/>
      <geometry>
        <mesh filename="package://dim_cpp/urdf/meshes/cameraholder-collision.stl" scale="0.001 0.001 0.001"/>
      </geometry>
      <material name="mat">
        <color rgba="0.8 0.8 0.8 1.0"/>
      </material>
    </collision>
    <inertial>
      <mass value=".05"/>
      <inertia ixx="3.1757907e-05" ixy="0" ixz="0" iyy="7.106668e-05" iyz="0" izz="4.4024575e-05"/>
      <origin rpy="0 0 0" xyz="0 0 .03"/>
    </inertial>
  </link>
  <joint name="camera_holder_joint" type="revolute">
    <parent link="tilt_base"/>
    <child link="camera_holder"/>
    <origin rpy="0 0 0" xyz="0 0 0.014"/>
    <axis xyz="1 0 0"/>
    <limit effort="100" lower="-1.57" upper="1.57" velocity="0.1"/>
  </joint>
</robot>
