<?xml version="1.0" ?>
<!-- =================================================================================== -->
<!-- |    This document was autogenerated by xacro from xarm_devkit_base_descr.urdf.xacro | -->
<!-- |    EDITING THIS FILE BY HAND IS NOT RECOMMENDED                                 | -->
<!-- =================================================================================== -->
<robot name="devkit_base_descr" xmlns:drake="http://drake.mit.edu">
  <!-- <xacro:devkit_base base_frame="world" base_pos_x="0.0" base_pos_y="0.0" base_pos_z="0.0" base_roll="0.0" base_pitch="0.0" base_yaw="0.0" r="0.8" g="0.8" b="0.8" a="1.0" /> -->
  <!-- <xacro:devkit_base base_frame="world" base_pos_x="0.0" base_pos_y="0.0" base_pos_z="0.0" base_roll="0.0" base_pitch="0.0" base_yaw="0.0" r="0.8" g="0.8" b="0.8" a="1.0" /> -->
  <link name="world"/>
  <link name="base_center"/>
  <joint name="base_parent_joint" type="fixed">
    <parent link="world"/>
    <child link="base_center"/>
    <origin rpy="0.0 0.0 0.0" xyz="0.0 0.0 0.23625"/>
  </joint>
  <link name="devkit_base_link">
    <visual>
      <origin rpy="0 0 0" xyz="0 0 0"/>
      <geometry>
        <mesh filename="package://dim_cpp/meshes/devkit_base/devkit_base_wheels_collision.stl" scale="1 1 1"/>
      </geometry>
      <material name="mat">
        <color rgba="0.8 0.8 0.8 1.0"/>
      </material>
    </visual>
    <inertial>
      <mass value="45"/>
      <inertia ixx="12.732327" ixy="0" ixz="0" iyy="12.513553" iyz="0" izz="1.8057749"/>
      <origin rpy="0 0 0" xyz=".225 -.2125 .9125"/>
    </inertial>
    <collision name="collision_0000">
      <origin rpy="0 0 0" xyz="0 0 0"/>
      <geometry>
        <mesh filename="package://dim_cpp/meshes/devkit_base/devkit_base_wheels_parts/devkit_base_wheels_convex_piece_000.obj">
          <drake:declare_convex/>
        </mesh>
      </geometry>
    </collision>
    <collision name="collision_0001">
      <origin rpy="0 0 0" xyz="0 0 0"/>
      <geometry>
        <mesh filename="package://dim_cpp/meshes/devkit_base/devkit_base_wheels_parts/devkit_base_wheels_convex_piece_001.obj">
          <drake:declare_convex/>
        </mesh>
      </geometry>
    </collision>
    <collision name="collision_0002">
      <origin rpy="0 0 0" xyz="0 0 0"/>
      <geometry>
        <mesh filename="package://dim_cpp/meshes/devkit_base/devkit_base_wheels_parts/devkit_base_wheels_convex_piece_002.obj">
          <drake:declare_convex/>
        </mesh>
      </geometry>
    </collision>
    <collision name="collision_0003">
      <origin rpy="0 0 0" xyz="0 0 0"/>
      <geometry>
        <mesh filename="package://dim_cpp/meshes/devkit_base/devkit_base_wheels_parts/devkit_base_wheels_convex_piece_003.obj">
          <drake:declare_convex/>
        </mesh>
      </geometry>
    </collision>
    <collision name="collision_0004">
      <origin rpy="0 0 0" xyz="0 0 0"/>
      <geometry>
        <mesh filename="package://dim_cpp/meshes/devkit_base/devkit_base_wheels_parts/devkit_base_wheels_convex_piece_004.obj">
          <drake:declare_convex/>
        </mesh>
      </geometry>
    </collision>
    <collision name="collision_0005">
      <origin rpy="0 0 0" xyz="0 0 0"/>
      <geometry>
        <mesh filename="package://dim_cpp/meshes/devkit_base/devkit_base_wheels_parts/devkit_base_wheels_convex_piece_005.obj">
          <drake:declare_convex/>
        </mesh>
      </geometry>
    </collision>
    <collision name="collision_0006">
      <origin rpy="0 0 0" xyz="0 0 0"/>
      <geometry>
        <mesh filename="package://dim_cpp/meshes/devkit_base/devkit_base_wheels_parts/devkit_base_wheels_convex_piece_006.obj">
          <drake:declare_convex/>
        </mesh>
      </geometry>
    </collision>
    <collision name="collision_0007">
      <origin rpy="0 0 0" xyz="0 0 0"/>
      <geometry>
        <mesh filename="package://dim_cpp/meshes/devkit_base/devkit_base_wheels_parts/devkit_base_wheels_convex_piece_007.obj">
          <drake:declare_convex/>
        </mesh>
      </geometry>
    </collision>
    <collision name="collision_0008">
      <origin rpy="0 0 0" xyz="0 0 0"/>
      <geometry>
        <mesh filename="package://dim_cpp/meshes/devkit_base/devkit_base_wheels_parts/devkit_base_wheels_convex_piece_008.obj">
          <drake:declare_convex/>
        </mesh>
      </geometry>
    </collision>
    <collision name="collision_0009">
      <origin rpy="0 0 0" xyz="0 0 0"/>
      <geometry>
        <mesh filename="package://dim_cpp/meshes/devkit_base/devkit_base_wheels_parts/devkit_base_wheels_convex_piece_009.obj">
          <drake:declare_convex/>
        </mesh>
      </geometry>
    </collision>
    <collision name="collision_0010">
      <origin rpy="0 0 0" xyz="0 0 0"/>
      <geometry>
        <mesh filename="package://dim_cpp/meshes/devkit_base/devkit_base_wheels_parts/devkit_base_wheels_convex_piece_010.obj">
          <drake:declare_convex/>
        </mesh>
      </geometry>
    </collision>
    <collision name="collision_0011">
      <origin rpy="0 0 0" xyz="0 0 0"/>
      <geometry>
        <mesh filename="package://dim_cpp/meshes/devkit_base/devkit_base_wheels_parts/devkit_base_wheels_convex_piece_011.obj">
          <drake:declare_convex/>
        </mesh>
      </geometry>
    </collision>
    <collision name="collision_0012">
      <origin rpy="0 0 0" xyz="0 0 0"/>
      <geometry>
        <mesh filename="package://dim_cpp/meshes/devkit_base/devkit_base_wheels_parts/devkit_base_wheels_convex_piece_012.obj">
          <drake:declare_convex/>
        </mesh>
      </geometry>
    </collision>
    <collision name="collision_0013">
      <origin rpy="0 0 0" xyz="0 0 0"/>
      <geometry>
        <mesh filename="package://dim_cpp/meshes/devkit_base/devkit_base_wheels_parts/devkit_base_wheels_convex_piece_013.obj">
          <drake:declare_convex/>
        </mesh>
      </geometry>
    </collision>
    <collision name="collision_0014">
      <origin rpy="0 0 0" xyz="0 0 0"/>
      <geometry>
        <mesh filename="package://dim_cpp/meshes/devkit_base/devkit_base_wheels_parts/devkit_base_wheels_convex_piece_014.obj">
          <drake:declare_convex/>
        </mesh>
      </geometry>
    </collision>
    <collision name="collision_0015">
      <origin rpy="0 0 0" xyz="0 0 0"/>
      <geometry>
        <mesh filename="package://dim_cpp/meshes/devkit_base/devkit_base_wheels_parts/devkit_base_wheels_convex_piece_015.obj">
          <drake:declare_convex/>
        </mesh>
      </geometry>
    </collision>
    <collision name="collision_0016">
      <origin rpy="0 0 0" xyz="0 0 0"/>
      <geometry>
        <mesh filename="package://dim_cpp/meshes/devkit_base/devkit_base_wheels_parts/devkit_base_wheels_convex_piece_016.obj">
          <drake:declare_convex/>
        </mesh>
      </geometry>
    </collision>
    <collision name="collision_0017">
      <origin rpy="0 0 0" xyz="0 0 0"/>
      <geometry>
        <mesh filename="package://dim_cpp/meshes/devkit_base/devkit_base_wheels_parts/devkit_base_wheels_convex_piece_017.obj">
          <drake:declare_convex/>
        </mesh>
      </geometry>
    </collision>
    <collision name="collision_0018">
      <origin rpy="0 0 0" xyz="0 0 0"/>
      <geometry>
        <mesh filename="package://dim_cpp/meshes/devkit_base/devkit_base_wheels_parts/devkit_base_wheels_convex_piece_018.obj">
          <drake:declare_convex/>
        </mesh>
      </geometry>
    </collision>
    <collision name="collision_0019">
      <origin rpy="0 0 0" xyz="0 0 0"/>
      <geometry>
        <mesh filename="package://dim_cpp/meshes/devkit_base/devkit_base_wheels_parts/devkit_base_wheels_convex_piece_019.obj">
          <drake:declare_convex/>
        </mesh>
      </geometry>
    </collision>
    <collision name="collision_0020">
      <origin rpy="0 0 0" xyz="0 0 0"/>
      <geometry>
        <mesh filename="package://dim_cpp/meshes/devkit_base/devkit_base_wheels_parts/devkit_base_wheels_convex_piece_020.obj">
          <drake:declare_convex/>
        </mesh>
      </geometry>
    </collision>
    <collision name="collision_0021">
      <origin rpy="0 0 0" xyz="0 0 0"/>
      <geometry>
        <mesh filename="package://dim_cpp/meshes/devkit_base/devkit_base_wheels_parts/devkit_base_wheels_convex_piece_021.obj">
          <drake:declare_convex/>
        </mesh>
      </geometry>
    </collision>
    <collision name="collision_0022">
      <origin rpy="0 0 0" xyz="0 0 0"/>
      <geometry>
        <mesh filename="package://dim_cpp/meshes/devkit_base/devkit_base_wheels_parts/devkit_base_wheels_convex_piece_022.obj">
          <drake:declare_convex/>
        </mesh>
      </geometry>
    </collision>
    <collision name="collision_0023">
      <origin rpy="0 0 0" xyz="0 0 0"/>
      <geometry>
        <mesh filename="package://dim_cpp/meshes/devkit_base/devkit_base_wheels_parts/devkit_base_wheels_convex_piece_023.obj">
          <drake:declare_convex/>
        </mesh>
      </geometry>
    </collision>
    <collision name="collision_0024">
      <origin rpy="0 0 0" xyz="0 0 0"/>
      <geometry>
        <mesh filename="package://dim_cpp/meshes/devkit_base/devkit_base_wheels_parts/devkit_base_wheels_convex_piece_024.obj">
          <drake:declare_convex/>
        </mesh>
      </geometry>
    </collision>
    <collision name="collision_0025">
      <origin rpy="0 0 0" xyz="0 0 0"/>
      <geometry>
        <mesh filename="package://dim_cpp/meshes/devkit_base/devkit_base_wheels_parts/devkit_base_wheels_convex_piece_025.obj">
          <drake:declare_convex/>
        </mesh>
      </geometry>
    </collision>
    <collision name="collision_0026">
      <origin rpy="0 0 0" xyz="0 0 0"/>
      <geometry>
        <mesh filename="package://dim_cpp/meshes/devkit_base/devkit_base_wheels_parts/devkit_base_wheels_convex_piece_026.obj">
          <drake:declare_convex/>
        </mesh>
      </geometry>
    </collision>
    <collision name="collision_0027">
      <origin rpy="0 0 0" xyz="0 0 0"/>
      <geometry>
        <mesh filename="package://dim_cpp/meshes/devkit_base/devkit_base_wheels_parts/devkit_base_wheels_convex_piece_027.obj">
          <drake:declare_convex/>
        </mesh>
      </geometry>
    </collision>
    <collision name="collision_0028">
      <origin rpy="0 0 0" xyz="0 0 0"/>
      <geometry>
        <mesh filename="package://dim_cpp/meshes/devkit_base/devkit_base_wheels_parts/devkit_base_wheels_convex_piece_028.obj">
          <drake:declare_convex/>
        </mesh>
      </geometry>
    </collision>
    <collision name="collision_0029">
      <origin rpy="0 0 0" xyz="0 0 0"/>
      <geometry>
        <mesh filename="package://dim_cpp/meshes/devkit_base/devkit_base_wheels_parts/devkit_base_wheels_convex_piece_029.obj">
          <drake:declare_convex/>
        </mesh>
      </geometry>
    </collision>
    <collision name="collision_0030">
      <origin rpy="0 0 0" xyz="0 0 0"/>
      <geometry>
        <mesh filename="package://dim_cpp/meshes/devkit_base/devkit_base_wheels_parts/devkit_base_wheels_convex_piece_030.obj">
          <drake:declare_convex/>
        </mesh>
      </geometry>
    </collision>
    <collision name="collision_0031">
      <origin rpy="0 0 0" xyz="0 0 0"/>
      <geometry>
        <mesh filename="package://dim_cpp/meshes/devkit_base/devkit_base_wheels_parts/devkit_base_wheels_convex_piece_031.obj">
          <drake:declare_convex/>
        </mesh>
      </geometry>
    </collision>
    <collision name="collision_0032">
      <origin rpy="0 0 0" xyz="0 0 0"/>
      <geometry>
        <mesh filename="package://dim_cpp/meshes/devkit_base/devkit_base_wheels_parts/devkit_base_wheels_convex_piece_032.obj">
          <drake:declare_convex/>
        </mesh>
      </geometry>
    </collision>
    <collision name="collision_0033">
      <origin rpy="0 0 0" xyz="0 0 0"/>
      <geometry>
        <mesh filename="package://dim_cpp/meshes/devkit_base/devkit_base_wheels_parts/devkit_base_wheels_convex_piece_033.obj">
          <drake:declare_convex/>
        </mesh>
      </geometry>
    </collision>
    <collision name="collision_0034">
      <origin rpy="0 0 0" xyz="0 0 0"/>
      <geometry>
        <mesh filename="package://dim_cpp/meshes/devkit_base/devkit_base_wheels_parts/devkit_base_wheels_convex_piece_034.obj">
          <drake:declare_convex/>
        </mesh>
      </geometry>
    </collision>
    <collision name="collision_0035">
      <origin rpy="0 0 0" xyz="0 0 0"/>
      <geometry>
        <mesh filename="package://dim_cpp/meshes/devkit_base/devkit_base_wheels_parts/devkit_base_wheels_convex_piece_035.obj">
          <drake:declare_convex/>
        </mesh>
      </geometry>
    </collision>
    <collision name="collision_0036">
      <origin rpy="0 0 0" xyz="0 0 0"/>
      <geometry>
        <mesh filename="package://dim_cpp/meshes/devkit_base/devkit_base_wheels_parts/devkit_base_wheels_convex_piece_036.obj">
          <drake:declare_convex/>
        </mesh>
      </geometry>
    </collision>
    <collision name="collision_0037">
      <origin rpy="0 0 0" xyz="0 0 0"/>
      <geometry>
        <mesh filename="package://dim_cpp/meshes/devkit_base/devkit_base_wheels_parts/devkit_base_wheels_convex_piece_037.obj">
          <drake:declare_convex/>
        </mesh>
      </geometry>
    </collision>
    <collision name="collision_0038">
      <origin rpy="0 0 0" xyz="0 0 0"/>
      <geometry>
        <mesh filename="package://dim_cpp/meshes/devkit_base/devkit_base_wheels_parts/devkit_base_wheels_convex_piece_038.obj">
          <drake:declare_convex/>
        </mesh>
      </geometry>
    </collision>
    <collision name="collision_0039">
      <origin rpy="0 0 0" xyz="0 0 0"/>
      <geometry>
        <mesh filename="package://dim_cpp/meshes/devkit_base/devkit_base_wheels_parts/devkit_base_wheels_convex_piece_039.obj">
          <drake:declare_convex/>
        </mesh>
      </geometry>
    </collision>
    <collision name="collision_0040">
      <origin rpy="0 0 0" xyz="0 0 0"/>
      <geometry>
        <mesh filename="package://dim_cpp/meshes/devkit_base/devkit_base_wheels_parts/devkit_base_wheels_convex_piece_040.obj">
          <drake:declare_convex/>
        </mesh>
      </geometry>
    </collision>
    <collision name="collision_0041">
      <origin rpy="0 0 0" xyz="0 0 0"/>
      <geometry>
        <mesh filename="package://dim_cpp/meshes/devkit_base/devkit_base_wheels_parts/devkit_base_wheels_convex_piece_041.obj">
          <drake:declare_convex/>
        </mesh>
      </geometry>
    </collision>
    <collision name="collision_0042">
      <origin rpy="0 0 0" xyz="0 0 0"/>
      <geometry>
        <mesh filename="package://dim_cpp/meshes/devkit_base/devkit_base_wheels_parts/devkit_base_wheels_convex_piece_042.obj">
          <drake:declare_convex/>
        </mesh>
      </geometry>
    </collision>
    <collision name="collision_0043">
      <origin rpy="0 0 0" xyz="0 0 0"/>
      <geometry>
        <mesh filename="package://dim_cpp/meshes/devkit_base/devkit_base_wheels_parts/devkit_base_wheels_convex_piece_043.obj">
          <drake:declare_convex/>
        </mesh>
      </geometry>
    </collision>
    <collision name="collision_0044">
      <origin rpy="0 0 0" xyz="0 0 0"/>
      <geometry>
        <mesh filename="package://dim_cpp/meshes/devkit_base/devkit_base_wheels_parts/devkit_base_wheels_convex_piece_044.obj">
          <drake:declare_convex/>
        </mesh>
      </geometry>
    </collision>
    <collision name="collision_0045">
      <origin rpy="0 0 0" xyz="0 0 0"/>
      <geometry>
        <mesh filename="package://dim_cpp/meshes/devkit_base/devkit_base_wheels_parts/devkit_base_wheels_convex_piece_045.obj">
          <drake:declare_convex/>
        </mesh>
      </geometry>
    </collision>
    <collision name="collision_0046">
      <origin rpy="0 0 0" xyz="0 0 0"/>
      <geometry>
        <mesh filename="package://dim_cpp/meshes/devkit_base/devkit_base_wheels_parts/devkit_base_wheels_convex_piece_046.obj">
          <drake:declare_convex/>
        </mesh>
      </geometry>
    </collision>
    <collision name="collision_0047">
      <origin rpy="0 0 0" xyz="0 0 0"/>
      <geometry>
        <mesh filename="package://dim_cpp/meshes/devkit_base/devkit_base_wheels_parts/devkit_base_wheels_convex_piece_047.obj">
          <drake:declare_convex/>
        </mesh>
      </geometry>
    </collision>
    <collision name="collision_0048">
      <origin rpy="0 0 0" xyz="0 0 0"/>
      <geometry>
        <mesh filename="package://dim_cpp/meshes/devkit_base/devkit_base_wheels_parts/devkit_base_wheels_convex_piece_048.obj">
          <drake:declare_convex/>
        </mesh>
      </geometry>
    </collision>
    <collision name="collision_0049">
      <origin rpy="0 0 0" xyz="0 0 0"/>
      <geometry>
        <mesh filename="package://dim_cpp/meshes/devkit_base/devkit_base_wheels_parts/devkit_base_wheels_convex_piece_049.obj">
          <drake:declare_convex/>
        </mesh>
      </geometry>
    </collision>
    <collision name="collision_0050">
      <origin rpy="0 0 0" xyz="0 0 0"/>
      <geometry>
        <mesh filename="package://dim_cpp/meshes/devkit_base/devkit_base_wheels_parts/devkit_base_wheels_convex_piece_050.obj">
          <drake:declare_convex/>
        </mesh>
      </geometry>
    </collision>
    <collision name="collision_0051">
      <origin rpy="0 0 0" xyz="0 0 0"/>
      <geometry>
        <mesh filename="package://dim_cpp/meshes/devkit_base/devkit_base_wheels_parts/devkit_base_wheels_convex_piece_051.obj">
          <drake:declare_convex/>
        </mesh>
      </geometry>
    </collision>
    <collision name="collision_0052">
      <origin rpy="0 0 0" xyz="0 0 0"/>
      <geometry>
        <mesh filename="package://dim_cpp/meshes/devkit_base/devkit_base_wheels_parts/devkit_base_wheels_convex_piece_052.obj">
          <drake:declare_convex/>
        </mesh>
      </geometry>
    </collision>
    <collision name="collision_0053">
      <origin rpy="0 0 0" xyz="0 0 0"/>
      <geometry>
        <mesh filename="package://dim_cpp/meshes/devkit_base/devkit_base_wheels_parts/devkit_base_wheels_convex_piece_053.obj">
          <drake:declare_convex/>
        </mesh>
      </geometry>
    </collision>
    <collision name="collision_0054">
      <origin rpy="0 0 0" xyz="0 0 0"/>
      <geometry>
        <mesh filename="package://dim_cpp/meshes/devkit_base/devkit_base_wheels_parts/devkit_base_wheels_convex_piece_054.obj">
          <drake:declare_convex/>
        </mesh>
      </geometry>
    </collision>
    <collision name="collision_0055">
      <origin rpy="0 0 0" xyz="0 0 0"/>
      <geometry>
        <mesh filename="package://dim_cpp/meshes/devkit_base/devkit_base_wheels_parts/devkit_base_wheels_convex_piece_055.obj">
          <drake:declare_convex/>
        </mesh>
      </geometry>
    </collision>
    <collision name="collision_0056">
      <origin rpy="0 0 0" xyz="0 0 0"/>
      <geometry>
        <mesh filename="package://dim_cpp/meshes/devkit_base/devkit_base_wheels_parts/devkit_base_wheels_convex_piece_056.obj">
          <drake:declare_convex/>
        </mesh>
      </geometry>
    </collision>
    <collision name="collision_0057">
      <origin rpy="0 0 0" xyz="0 0 0"/>
      <geometry>
        <mesh filename="package://dim_cpp/meshes/devkit_base/devkit_base_wheels_parts/devkit_base_wheels_convex_piece_057.obj">
          <drake:declare_convex/>
        </mesh>
      </geometry>
    </collision>
    <collision name="collision_0058">
      <origin rpy="0 0 0" xyz="0 0 0"/>
      <geometry>
        <mesh filename="package://dim_cpp/meshes/devkit_base/devkit_base_wheels_parts/devkit_base_wheels_convex_piece_058.obj">
          <drake:declare_convex/>
        </mesh>
      </geometry>
    </collision>
    <collision name="collision_0059">
      <origin rpy="0 0 0" xyz="0 0 0"/>
      <geometry>
        <mesh filename="package://dim_cpp/meshes/devkit_base/devkit_base_wheels_parts/devkit_base_wheels_convex_piece_059.obj">
          <drake:declare_convex/>
        </mesh>
      </geometry>
    </collision>
    <collision name="collision_0060">
      <origin rpy="0 0 0" xyz="0 0 0"/>
      <geometry>
        <mesh filename="package://dim_cpp/meshes/devkit_base/devkit_base_wheels_parts/devkit_base_wheels_convex_piece_060.obj">
          <drake:declare_convex/>
        </mesh>
      </geometry>
    </collision>
    <collision name="collision_0061">
      <origin rpy="0 0 0" xyz="0 0 0"/>
      <geometry>
        <mesh filename="package://dim_cpp/meshes/devkit_base/devkit_base_wheels_parts/devkit_base_wheels_convex_piece_061.obj">
          <drake:declare_convex/>
        </mesh>
      </geometry>
    </collision>
    <collision name="collision_0062">
      <origin rpy="0 0 0" xyz="0 0 0"/>
      <geometry>
        <mesh filename="package://dim_cpp/meshes/devkit_base/devkit_base_wheels_parts/devkit_base_wheels_convex_piece_062.obj">
          <drake:declare_convex/>
        </mesh>
      </geometry>
    </collision>
    <collision name="collision_0063">
      <origin rpy="0 0 0" xyz="0 0 0"/>
      <geometry>
        <mesh filename="package://dim_cpp/meshes/devkit_base/devkit_base_wheels_parts/devkit_base_wheels_convex_piece_063.obj">
          <drake:declare_convex/>
        </mesh>
      </geometry>
    </collision>
  </link>
  <joint name="base_center_joint" type="fixed">
    <parent link="base_center"/>
    <child link="devkit_base_link"/>
    <origin rpy="0 0 1.5707" xyz="0 0 0"/>
  </joint>
  <link name="pan_tilt_base">
    <visual>
      <origin rpy="0 0 0" xyz="0 0 0"/>
      <geometry>
        <mesh filename="package://dim_cpp/meshes/devkit_base/pan_tilt_base_collision.stl" scale="1 1 1"/>
      </geometry>
      <material name="mat">
        <color rgba="0.8 0.8 0.8 1.0"/>
      </material>
    </visual>
    <collision>
      <origin rpy="0 0 0" xyz="0 0 0"/>
      <geometry>
        <mesh filename="package://dim_cpp/meshes/devkit_base/pan_tilt_base_collision.stl" scale="1 1 1"/>
      </geometry>
      <material name="mat">
        <color rgba="0.8 0.8 0.8 1.0"/>
      </material>
    </collision>
  </link>
  <joint name="pan_tilt_base_joint" type="fixed">
    <parent link="devkit_base_link"/>
    <child link="pan_tilt_base"/>
    <origin rpy="0 0 0" xyz="0 0 0"/>
  </joint>
  <link name="pan_tilt_pan">
    <visual>
      <origin rpy="0 0 0" xyz="0 -.1325 0"/>
      <geometry>
        <mesh filename="package://dim_cpp/meshes/devkit_base/pan_tilt_pan_collision.stl" scale="1 1 1"/>
      </geometry>
      <material name="mat">
        <color rgba="0.8 0.8 0.8 1.0"/>
      </material>
    </visual>
    <collision>
      <origin rpy="0 0 0" xyz="0 -.1325 0"/>
      <geometry>
        <mesh filename="package://dim_cpp/meshes/devkit_base/pan_tilt_pan_collision.stl" scale="1 1 1"/>
      </geometry>
      <material name="mat">
        <color rgba="0.8 0.8 0.8 1.0"/>
      </material>
    </collision>
  </link>
  <joint name="pan_tilt_pan_joint" type="revolute">
    <parent link="pan_tilt_base"/>
    <child link="pan_tilt_pan"/>
    <origin rpy="0 0 0" xyz="0 .1325 0"/>
    <axis xyz="0 0 1"/>
    <limit effort="100" lower="-3.14" upper="3.14" velocity="1"/>
  </joint>
  <link name="pan_tilt_head">
    <visual>
      <origin rpy="0 0 0" xyz="0 -.1325 -1.659"/>
      <geometry>
        <mesh filename="package://dim_cpp/meshes/devkit_base/pan_tilt_head_collision.stl" scale="1 1 1"/>
      </geometry>
      <material name="mat">
        <color rgba="0.8 0.8 0.8 1.0"/>
      </material>
    </visual>
    <collision>
      <origin rpy="0 0 0" xyz="0 -.1325 -1.659"/>
      <geometry>
        <mesh filename="package://dim_cpp/meshes/devkit_base/pan_tilt_head_collision.stl" scale="1 1 1"/>
      </geometry>
      <material name="mat">
        <color rgba="0.8 0.8 0.8 1.0"/>
      </material>
    </collision>
  </link>
  <joint name="pan_tilt_head_joint" type="revolute">
    <parent link="pan_tilt_pan"/>
    <child link="pan_tilt_head"/>
    <origin rpy="0 0 0" xyz="0 0 1.659"/>
    <axis xyz="1 0 0"/>
    <limit effort="100" lower="-1.57" upper="1.57" velocity="1"/>
  </joint>
  <link name="camera_center_link"/>
  <joint name="camera_center_joint" type="fixed">
    <parent link="pan_tilt_head"/>
    <child link="camera_center_link"/>
    <origin rpy="0 0 0" xyz="0 0.027 .057055"/>
  </joint>
  <link name="pillar_platform">
    <visual>
      <origin rpy="0 0 0" xyz="0 0 0"/>
      <geometry>
        <mesh filename="package://dim_cpp/meshes/devkit_base/pillar_platform_collision.stl" scale="1 1 1"/>
      </geometry>
      <material name="mat">
        <color rgba="0.8 0.8 0.8 1.0"/>
      </material>
    </visual>
    <collision>
      <origin rpy="0 0 0" xyz="0 0 0"/>
      <geometry>
        <mesh filename="package://dim_cpp/meshes/devkit_base/pillar_platform_collision.stl" scale="1 1 1"/>
      </geometry>
      <material name="mat">
        <color rgba="0.8 0.8 0.8 1.0"/>
      </material>
    </collision>
    <inertial>
      <mass value="1.5"/>
      <inertia ixx="0.008729344" ixy="0" ixz="0" iyy="0.0085796565" iyz="0" izz="0.01050275"/>
      <origin rpy="0 0 0" xyz=".225 -.365 1.41"/>
    </inertial>
  </link>
  <joint name="pillar_platform_joint" type="prismatic">
    <parent link="devkit_base_link"/>
    <child link="pillar_platform"/>
    <origin rpy="0 0 0" xyz="0 0 0"/>
    <axis xyz="0 0 1"/>
    <limit effort="100" lower="-0.65" upper="0.0" velocity="0.1"/>
  </joint>
  <link name="piper_angled_mount">
    <visual>
      <origin rpy="0 0 0" xyz="0 0 0"/>
      <geometry>
        <mesh filename="package://dim_cpp/meshes/devkit_base/piper_angled_mount_collision.stl" scale="1 1 1"/>
      </geometry>
      <material name="mat">
        <color rgba="0.8 0.8 0.8 1.0"/>
      </material>
    </visual>
    <collision>
      <origin rpy="0 0 0" xyz="0 0 0"/>
      <geometry>
        <mesh filename="package://dim_cpp/meshes/devkit_base/piper_angled_mount_collision.stl" scale="1 1 1"/>
      </geometry>
      <material name="mat">
        <color rgba="0.8 0.8 0.8 1.0"/>
      </material>
    </collision>
    <inertial>
      <mass value="1.5"/>
      <inertia ixx="0.008729344" ixy="0" ixz="0" iyy="0.0085796565" iyz="0" izz="0.01050275"/>
      <origin rpy="0 0 0" xyz=".225 -.365 1.41"/>
    </inertial>
  </link>
  <joint name="piper_mount_joint" type="fixed">
    <parent link="pillar_platform"/>
    <child link="piper_angled_mount"/>
    <origin rpy="0.0 0.0 0.0" xyz="0.0 0.0 0.0"/>
  </joint>
  <!-- Insert at the beginning of xarm_device_macro.xacro -->
  <material name="Black">
    <color rgba="0.0 0.0 0.0 1.0"/>
  </material>
  <material name="Red">
    <color rgba="0.8 0.0 0.0 1.0"/>
  </material>
  <material name="White">
    <color rgba="1.0 1.0 1.0 1.0"/>
  </material>
  <material name="Silver">
    <color rgba="0.753 0.753 0.753 1.0"/>
  </material>
  <joint name="world_joint" type="fixed">
    <parent link="piper_angled_mount"/>
    <child link="link_base"/>
    <origin rpy="0 0.7854 1.5707" xyz="0 0.292645 1.42886"/>
  </joint>
  <ros2_control name="uf_robot_hardware/UFFakeRobotSystemHardware" type="system">
    <hardware>
      <plugin>uf_robot_hardware/UFFakeRobotSystemHardware</plugin>
    </hardware>
    <joint name="joint1">
      <command_interface name="position">
        <param name="min">-6.283185307179586</param>
        <param name="max">6.283185307179586</param>
      </command_interface>
      <command_interface name="velocity">
        <param name="min">-3.14</param>
        <param name="max">3.14</param>
      </command_interface>
      <state_interface name="position"/>
      <state_interface name="velocity"/>
      <!-- <state_interface name="effort"/> -->
    </joint>
    <joint name="joint2">
      <command_interface name="position">
        <param name="min">-2.059</param>
        <param name="max">2.0944</param>
      </command_interface>
      <command_interface name="velocity">
        <param name="min">-3.14</param>
        <param name="max">3.14</param>
      </command_interface>
      <state_interface name="position"/>
      <state_interface name="velocity"/>
      <!-- <state_interface name="effort"/> -->
    </joint>
    <joint name="joint3">
      <command_interface name="position">
        <param name="min">-6.283185307179586</param>
        <param name="max">6.283185307179586</param>
      </command_interface>
      <command_interface name="velocity">
        <param name="min">-3.14</param>
        <param name="max">3.14</param>
      </command_interface>
      <state_interface name="position"/>
      <state_interface name="velocity"/>
      <!-- <state_interface name="effort"/> -->
    </joint>
    <joint name="joint4">
      <command_interface name="position">
        <param name="min">-0.19198</param>
        <param name="max">3.927</param>
      </command_interface>
      <command_interface name="velocity">
        <param name="min">-3.14</param>
        <param name="max">3.14</param>
      </command_interface>
      <state_interface name="position"/>
      <state_interface name="velocity"/>
      <!-- <state_interface name="effort"/> -->
    </joint>
    <joint name="joint5">
      <command_interface name="position">
        <param name="min">-6.283185307179586</param>
        <param name="max">6.283185307179586</param>
      </command_interface>
      <command_interface name="velocity">
        <param name="min">-3.14</param>
        <param name="max">3.14</param>
      </command_interface>
      <state_interface name="position"/>
      <state_interface name="velocity"/>
      <!-- <state_interface name="effort"/> -->
    </joint>
    <joint name="joint6">
      <command_interface name="position">
        <param name="min">-1.69297</param>
        <param name="max">3.141592653589793</param>
      </command_interface>
      <command_interface name="velocity">
        <param name="min">-3.14</param>
        <param name="max">3.14</param>
      </command_interface>
      <state_interface name="position"/>
      <state_interface name="velocity"/>
      <!-- <state_interface name="effort"/> -->
    </joint>
    <joint name="joint7">
      <command_interface name="position">
        <param name="min">-6.283185307179586</param>
        <param name="max">6.283185307179586</param>
      </command_interface>
      <command_interface name="velocity">
        <param name="min">-3.14</param>
        <param name="max">3.14</param>
      </command_interface>
      <state_interface name="position"/>
      <state_interface name="velocity"/>
      <!-- <state_interface name="effort"/> -->
    </joint>
  </ros2_control>
  <link name="link_base">
    <inertial>
      <origin rpy="0 0 0" xyz="-0.021131 -0.0016302 0.056488"/>
      <mass value="0.88556"/>
      <inertia ixx="0.0030595" ixy="0.00012259" ixz="-0.00062705" iyy="0.0037783" iyz="0.00027023" izz="0.0020125"/>
    </inertial>
    <visual>
      <geometry>
        <mesh filename="package://xarm_description/meshes/xarm7/visual/link_base.stl"/>
      </geometry>
      <origin rpy="0 0 0" xyz="0 0 0"/>
      <material name="White"/>
    </visual>
    <collision>
      <geometry>
        <mesh filename="package://xarm_description/meshes/xarm7/visual/link_base.stl"/>
      </geometry>
      <origin rpy="0 0 0" xyz="0 0 0"/>
    </collision>
  </link>
  <link name="link1">
    <inertial>
      <origin rpy="0 0 0" xyz="-0.0002 0.02905 -0.01233"/>
      <mass value="2.382"/>
      <inertia ixx="0.0056905" ixy="-1.579e-05" ixz="5.125e-06" iyy="0.0049566" iyz="-0.000873378" izz="0.003316654"/>
    </inertial>
    <visual>
      <geometry>
        <mesh filename="package://xarm_description/meshes/xarm7/visual/link1.stl"/>
      </geometry>
      <origin rpy="0 0 0" xyz="0 0 0"/>
      <material name="White"/>
    </visual>
    <collision>
      <geometry>
        <mesh filename="package://xarm_description/meshes/xarm7/visual/link1.stl"/>
      </geometry>
      <origin rpy="0 0 0" xyz="0 0 0"/>
    </collision>
  </link>
  <joint name="joint1" type="revolute">
    <origin rpy="0 0 0" xyz="0 0 0.267"/>
    <parent link="link_base"/>
    <child link="link1"/>
    <axis xyz="0 0 1"/>
    <limit effort="50" lower="-6.283185307179586" upper="6.283185307179586" velocity="3.14"/>
    <dynamics damping="10" friction="1"/>
  </joint>
  <link name="link2">
    <inertial>
      <origin rpy="0 0 0" xyz="0.00022 -0.12856 0.01735"/>
      <mass value="1.869"/>
      <inertia ixx="0.0095989" ixy="1.541e-06" ixz="5.56e-06" iyy="0.00382472" iyz="-0.00317156" izz="0.007565669"/>
    </inertial>
    <visual>
      <geometry>
        <mesh filename="package://xarm_description/meshes/xarm7/visual/link2.stl"/>
      </geometry>
      <origin rpy="0 0 0" xyz="0 0 0"/>
      <material name="White"/>
    </visual>
    <collision>
      <geometry>
        <mesh filename="package://xarm_description/meshes/xarm7/visual/link2.stl"/>
      </geometry>
      <origin rpy="0 0 0" xyz="0 0 0"/>
    </collision>
  </link>
  <joint name="joint2" type="revolute">
    <origin rpy="-1.5708 0 0" xyz="0 0 0"/>
    <parent link="link1"/>
    <child link="link2"/>
    <axis xyz="0 0 1"/>
    <limit effort="50" lower="-2.059" upper="2.0944" velocity="3.14"/>
    <dynamics damping="10" friction="1"/>
  </joint>
  <link name="link3">
    <inertial>
      <origin rpy="0 0 0" xyz="0.0466 -0.02463 -0.00768"/>
      <mass value="1.6383"/>
      <inertia ixx="0.00310955" ixy="0.00030837" ixz="-0.00058453" iyy="0.00264483" iyz="0.000338893" izz="0.0026624"/>
    </inertial>
    <visual>
      <geometry>
        <mesh filename="package://xarm_description/meshes/xarm7/visual/link3.stl"/>
      </geometry>
      <origin rpy="0 0 0" xyz="0 0 0"/>
      <material name="White"/>
    </visual>
    <collision>
      <geometry>
        <mesh filename="package://xarm_description/meshes/xarm7/visual/link3.stl"/>
      </geometry>
      <origin rpy="0 0 0" xyz="0 0 0"/>
    </collision>
  </link>
  <joint name="joint3" type="revolute">
    <origin rpy="1.5708 0 0" xyz="0 -0.293 0"/>
    <parent link="link2"/>
    <child link="link3"/>
    <axis xyz="0 0 1"/>
    <limit effort="30" lower="-6.283185307179586" upper="6.283185307179586" velocity="3.14"/>
    <dynamics damping="5" friction="1"/>
  </joint>
  <link name="link4">
    <inertial>
      <origin rpy="0 0 0" xyz="0.07047 -0.11575 0.012"/>
      <mass value="1.7269"/>
      <inertia ixx="0.005889" ixy="0.00137112" ixz="0.00088143" iyy="0.00359703" iyz="-0.001762155" izz="0.00543244"/>
    </inertial>
    <visual>
      <geometry>
        <mesh filename="package://xarm_description/meshes/xarm7/visual/link4.stl"/>
      </geometry>
      <origin rpy="0 0 0" xyz="0 0 0"/>
      <material name="White"/>
    </visual>
    <collision>
      <geometry>
        <mesh filename="package://xarm_description/meshes/xarm7/visual/link4.stl"/>
      </geometry>
      <origin rpy="0 0 0" xyz="0 0 0"/>
    </collision>
  </link>
  <joint name="joint4" type="revolute">
    <origin rpy="1.5708 0 0" xyz="0.0525 0 0"/>
    <parent link="link3"/>
    <child link="link4"/>
    <axis xyz="0 0 1"/>
    <limit effort="30" lower="-0.19198" upper="3.927" velocity="3.14"/>
    <dynamics damping="5" friction="1"/>
  </joint>
  <link name="link5">
    <inertial>
      <origin rpy="0 0 0" xyz="-0.00032 0.01604 -0.026"/>
      <mass value="1.3203"/>
      <inertia ixx="0.00534665" ixy="1.5117e-05" ixz="-3.69e-07" iyy="0.0049779" iyz="-0.00022132" izz="0.0013624"/>
    </inertial>
    <visual>
      <geometry>
        <mesh filename="package://xarm_description/meshes/xarm7/visual/link5.stl"/>
      </geometry>
      <origin rpy="0 0 0" xyz="0 0 0"/>
      <material name="White"/>
    </visual>
    <collision>
      <geometry>
        <mesh filename="package://xarm_description/meshes/xarm7/visual/link5.stl"/>
      </geometry>
      <origin rpy="0 0 0" xyz="0 0 0"/>
    </collision>
  </link>
  <joint name="joint5" type="revolute">
    <origin rpy="1.5708 0 0" xyz="0.0775 -0.3425 0"/>
    <parent link="link4"/>
    <child link="link5"/>
    <axis xyz="0 0 1"/>
    <limit effort="30" lower="-6.283185307179586" upper="6.283185307179586" velocity="3.14"/>
    <dynamics damping="5" friction="1"/>
  </joint>
  <link name="link6">
    <inertial>
      <origin rpy="0 0 0" xyz="0.06469 0.03278 0.02141"/>
      <mass value="1.325"/>
      <inertia ixx="0.0014745" ixy="-0.000488" ixz="0.0002953" iyy="0.0019037" iyz="0.00014749" izz="0.0023652"/>
    </inertial>
    <visual>
      <geometry>
        <mesh filename="package://xarm_description/meshes/xarm7/visual/link6.stl"/>
      </geometry>
      <origin rpy="0 0 0" xyz="0 0 0"/>
      <material name="White"/>
    </visual>
    <collision>
      <geometry>
        <mesh filename="package://xarm_description/meshes/xarm7/visual/link6.stl"/>
      </geometry>
      <origin rpy="0 0 0" xyz="0 0 0"/>
    </collision>
  </link>
  <joint name="joint6" type="revolute">
    <origin rpy="1.5708 0 0" xyz="0 0 0"/>
    <parent link="link5"/>
    <child link="link6"/>
    <axis xyz="0 0 1"/>
    <limit effort="20" lower="-1.69297" upper="3.141592653589793" velocity="3.14"/>
    <dynamics damping="2" friction="1"/>
  </joint>
  <link name="link7">
    <inertial>
      <origin rpy="0 0 0" xyz="0 -0.00677 -0.01098"/>
      <mass value="0.17"/>
      <inertia ixx="9.3e-05" ixy="-0.0" ixz="-0.0" iyy="5.87e-05" iyz="-3.6e-06" izz="0.000132"/>
    </inertial>
    <visual>
      <geometry>
        <mesh filename="package://xarm_description/meshes/xarm7/visual/link7.stl"/>
      </geometry>
      <origin rpy="0 0 0" xyz="0 0 0"/>
      <material name="Silver"/>
    </visual>
    <collision>
      <geometry>
        <mesh filename="package://xarm_description/meshes/end_tool/collision/end_tool.stl"/>
      </geometry>
      <origin rpy="0 0 0" xyz="0 0 0"/>
    </collision>
  </link>
  <joint name="joint7" type="revolute">
    <origin rpy="-1.5708 0 0" xyz="0.076 0.097 0"/>
    <parent link="link6"/>
    <child link="link7"/>
    <axis xyz="0 0 1"/>
    <limit effort="20" lower="-6.283185307179586" upper="6.283185307179586" velocity="3.14"/>
    <dynamics damping="2" friction="1"/>
  </joint>
  <!-- <link name="${prefix}link_eef" />
    <joint name="${prefix}joint_eef" type="fixed">
      <origin xyz="0 0 0" rpy="0 0 0" />
      <parent link="${prefix}link7" />
      <child link="${prefix}link_eef" />
    </joint> -->
  <transmission name="tran1">
    <type>transmission_interface/SimpleTransmission</type>
    <joint name="joint1">
      <hardwareInterface>hardware_interface/PositionJointInterface</hardwareInterface>
    </joint>
    <actuator name="motor1">
      <hardwareInterface>hardware_interface/PositionJointInterface</hardwareInterface>
      <mechanicalReduction>100</mechanicalReduction>
    </actuator>
  </transmission>
  <transmission name="tran2">
    <type>transmission_interface/SimpleTransmission</type>
    <joint name="joint2">
      <hardwareInterface>hardware_interface/PositionJointInterface</hardwareInterface>
    </joint>
    <actuator name="motor2">
      <hardwareInterface>hardware_interface/PositionJointInterface</hardwareInterface>
      <mechanicalReduction>100</mechanicalReduction>
    </actuator>
  </transmission>
  <transmission name="tran3">
    <type>transmission_interface/SimpleTransmission</type>
    <joint name="joint3">
      <hardwareInterface>hardware_interface/PositionJointInterface</hardwareInterface>
    </joint>
    <actuator name="motor3">
      <hardwareInterface>hardware_interface/PositionJointInterface</hardwareInterface>
      <mechanicalReduction>100</mechanicalReduction>
    </actuator>
  </transmission>
  <transmission name="tran4">
    <type>transmission_interface/SimpleTransmission</type>
    <joint name="joint4">
      <hardwareInterface>hardware_interface/PositionJointInterface</hardwareInterface>
    </joint>
    <actuator name="motor4">
      <hardwareInterface>hardware_interface/PositionJointInterface</hardwareInterface>
      <mechanicalReduction>100</mechanicalReduction>
    </actuator>
  </transmission>
  <transmission name="tran5">
    <type>transmission_interface/SimpleTransmission</type>
    <joint name="joint5">
      <hardwareInterface>hardware_interface/PositionJointInterface</hardwareInterface>
    </joint>
    <actuator name="motor5">
      <hardwareInterface>hardware_interface/PositionJointInterface</hardwareInterface>
      <mechanicalReduction>100</mechanicalReduction>
    </actuator>
  </transmission>
  <transmission name="tran6">
    <type>transmission_interface/SimpleTransmission</type>
    <joint name="joint6">
      <hardwareInterface>hardware_interface/PositionJointInterface</hardwareInterface>
    </joint>
    <actuator name="motor6">
      <hardwareInterface>hardware_interface/PositionJointInterface</hardwareInterface>
      <mechanicalReduction>100</mechanicalReduction>
    </actuator>
  </transmission>
  <transmission name="tran7">
    <type>transmission_interface/SimpleTransmission</type>
    <joint name="joint7">
      <hardwareInterface>hardware_interface/PositionJointInterface</hardwareInterface>
    </joint>
    <actuator name="motor7">
      <hardwareInterface>hardware_interface/PositionJointInterface</hardwareInterface>
      <mechanicalReduction>100</mechanicalReduction>
    </actuator>
  </transmission>
  <gazebo reference="link_base">
    <selfCollide>true</selfCollide>
  </gazebo>
  <gazebo reference="link1">
    <selfCollide>true</selfCollide>
  </gazebo>
  <gazebo reference="link2">
    <selfCollide>true</selfCollide>
  </gazebo>
  <gazebo reference="link3">
    <selfCollide>true</selfCollide>
  </gazebo>
  <gazebo reference="link4">
    <selfCollide>true</selfCollide>
  </gazebo>
  <gazebo reference="link5">
    <selfCollide>true</selfCollide>
  </gazebo>
  <gazebo reference="link6">
    <selfCollide>true</selfCollide>
  </gazebo>
  <gazebo reference="link7">
    <selfCollide>true</selfCollide>
  </gazebo>
  <link name="link_eef"/>
  <joint name="joint_eef" type="fixed">
    <origin rpy="0 0 0" xyz="0 0 0"/>
    <parent link="link7"/>
    <child link="link_eef"/>
  </joint>
  <ros2_control name="XArmGripperSystem" type="system">
    <hardware>
      <plugin>uf_robot_hardware/UFFakeRobotSystemHardware</plugin>
    </hardware>
    <joint name="drive_joint">
      <command_interface name="position">
        </command_interface>
      <command_interface name="velocity">
        <param name="min">-3.14</param>
        <param name="max">3.14</param>
      </command_interface>
      <state_interface name="position"/>
      <state_interface name="velocity"/>
      <!-- <state_interface name="effort"/> -->
    </joint>
  </ros2_control>
  <joint name="gripper_fix" type="fixed">
    <parent link="link_eef"/>
    <child link="xarm_gripper_base_link"/>
    <origin rpy="0 0 0" xyz="0 0 0"/>
  </joint>
  <link name="xarm_gripper_base_link">
    <inertial>
      <origin rpy="0 0 0" xyz="-0.00065489 -0.0018497 0.048028"/>
      <mass value="0.54156"/>
      <inertia ixx="0.00047106" ixy="3.9292E-07" ixz="2.6537E-06" iyy="0.00033072" iyz="-1.0975E-05" izz="0.00025642"/>
    </inertial>
    <visual>
      <geometry>
        <mesh filename="package://xarm_description/meshes/gripper/xarm/base_link.stl"/>
      </geometry>
      <origin rpy="0 0 0" xyz="0 0 0"/>
      <material name="White"/>
    </visual>
    <collision>
      <geometry>
        <mesh filename="package://xarm_description/meshes/gripper/xarm/base_link.stl"/>
      </geometry>
      <origin rpy="0 0 0" xyz="0 0 0"/>
    </collision>
  </link>
  <link name="left_outer_knuckle">
    <inertial>
      <origin rpy="0 0 0" xyz="2.9948E-14 0.021559 0.015181"/>
      <mass value="0.033618"/>
      <inertia ixx="1.9111E-05" ixy="-1.8803E-17" ixz="-1.1002E-17" iyy="6.6256E-06" iyz="-7.3008E-06" izz="1.3185E-05"/>
    </inertial>
    <visual>
      <geometry>
        <mesh filename="package://xarm_description/meshes/gripper/xarm/left_outer_knuckle.stl"/>
      </geometry>
      <origin rpy="0 0 0" xyz="0 0 0"/>
      <material name="Silver"/>
    </visual>
    <collision>
      <geometry>
        <mesh filename="package://xarm_description/meshes/gripper/xarm/left_outer_knuckle.stl"/>
      </geometry>
      <origin rpy="0 0 0" xyz="0 0 0"/>
    </collision>
  </link>
  <joint name="drive_joint" type="revolute">
    <origin rpy="0 0 0" xyz="0 0.035 0.059098"/>
    <parent link="xarm_gripper_base_link"/>
    <child link="left_outer_knuckle"/>
    <axis xyz="1 0 0"/>
    <limit effort="50" lower="0" upper="0.85" velocity="2"/>
  </joint>
  <link name="left_finger">
    <inertial>
      <origin rpy="0 0 0" xyz="-2.4536E-14 -0.016413 0.029258"/>
      <mass value="0.048304"/>
      <inertia ixx="1.7493E-05" ixy="-4.2156E-19" ixz="6.9164E-18" iyy="1.7225E-05" iyz="4.6433E-06" izz="5.1466E-06"/>
    </inertial>
    <visual>
      <geometry>
        <mesh filename="package://xarm_description/meshes/gripper/xarm/left_finger.stl"/>
      </geometry>
      <origin rpy="0 0 0" xyz="0 0 0"/>
      <material name="Silver"/>
    </visual>
    <collision>
      <geometry>
        <mesh filename="package://xarm_description/meshes/gripper/xarm/left_finger.stl"/>
      </geometry>
      <origin rpy="0 0 0" xyz="0 0 0"/>
    </collision>
  </link>
  <joint name="left_finger_joint" type="revolute">
    <origin rpy="0 0 0" xyz="0 0.035465 0.042039"/>
    <parent link="left_outer_knuckle"/>
    <child link="left_finger"/>
    <axis xyz="-1 0 0"/>
    <limit effort="50" lower="0" upper="0.85" velocity="2"/>
    <mimic joint="drive_joint" multiplier="1" offset="0"/>
  </joint>
  <link name="left_inner_knuckle">
    <inertial>
      <origin rpy="0 0 0" xyz="1.86600784687907E-06 0.0220467847633621 0.0261334672830885"/>
      <mass value="0.0230125781256706"/>
      <inertia ixx="6.09490024271906E-06" ixy="6.06651326160071E-11" ixz="7.19102670500635E-11" iyy="6.01955084375188E-06" iyz="-2.75316812991721E-06" izz="5.07862004479903E-06"/>
    </inertial>
    <visual>
      <geometry>
        <mesh filename="package://xarm_description/meshes/gripper/xarm/left_inner_knuckle.stl"/>
      </geometry>
      <origin rpy="0 0 0" xyz="0 0 0"/>
      <material name="Silver"/>
    </visual>
    <collision>
      <geometry>
        <mesh filename="package://xarm_description/meshes/gripper/xarm/left_inner_knuckle.stl"/>
      </geometry>
      <origin rpy="0 0 0" xyz="0 0 0"/>
    </collision>
  </link>
  <joint name="left_inner_knuckle_joint" type="revolute">
    <origin rpy="0 0 0" xyz="0 0.02 0.074098"/>
    <parent link="xarm_gripper_base_link"/>
    <child link="left_inner_knuckle"/>
    <axis xyz="1 0 0"/>
    <limit effort="50" lower="0" upper="0.85" velocity="2"/>
    <mimic joint="drive_joint" multiplier="1" offset="0"/>
  </joint>
  <link name="right_outer_knuckle">
    <inertial>
      <origin rpy="0 0 0" xyz="-3.1669E-14 -0.021559 0.015181"/>
      <mass value="0.033618"/>
      <inertia ixx="1.9111E-05" ixy="-1.8789E-17" ixz="1.0986E-17" iyy="6.6256E-06" iyz="7.3008E-06" izz="1.3185E-05"/>
    </inertial>
    <visual>
      <geometry>
        <mesh filename="package://xarm_description/meshes/gripper/xarm/right_outer_knuckle.stl"/>
      </geometry>
      <origin rpy="0 0 0" xyz="0 0 0"/>
      <material name="Silver"/>
    </visual>
    <collision>
      <geometry>
        <mesh filename="package://xarm_description/meshes/gripper/xarm/right_outer_knuckle.stl"/>
      </geometry>
      <origin rpy="0 0 0" xyz="0 0 0"/>
    </collision>
  </link>
  <joint name="right_outer_knuckle_joint" type="revolute">
    <origin rpy="0 0 0" xyz="0 -0.035 0.059098"/>
    <parent link="xarm_gripper_base_link"/>
    <child link="right_outer_knuckle"/>
    <axis xyz="-1 0 0"/>
    <limit effort="50" lower="0" upper="0.85" velocity="2"/>
    <mimic joint="drive_joint" multiplier="1" offset="0"/>
  </joint>
  <link name="right_finger">
    <inertial>
      <origin rpy="0 0 0" xyz="2.5618E-14 0.016413 0.029258"/>
      <mass value="0.048304"/>
      <inertia ixx="1.7493E-05" ixy="-5.0014E-19" ixz="-7.5079E-18" iyy="1.7225E-05" iyz="-4.6435E-06" izz="5.1466E-06"/>
    </inertial>
    <visual>
      <geometry>
        <mesh filename="package://xarm_description/meshes/gripper/xarm/right_finger.stl"/>
      </geometry>
      <origin rpy="0 0 0" xyz="0 0 0"/>
      <material name="Silver"/>
    </visual>
    <collision>
      <geometry>
        <mesh filename="package://xarm_description/meshes/gripper/xarm/right_finger.stl"/>
      </geometry>
      <origin rpy="0 0 0" xyz="0 0 0"/>
    </collision>
  </link>
  <joint name="right_finger_joint" type="revolute">
    <origin rpy="0 0 0" xyz="0 -0.035465 0.042039"/>
    <parent link="right_outer_knuckle"/>
    <child link="right_finger"/>
    <axis xyz="1 0 0"/>
    <limit effort="50" lower="0" upper="0.85" velocity="2"/>
    <mimic joint="drive_joint" multiplier="1" offset="0"/>
  </joint>
  <link name="right_inner_knuckle">
    <inertial>
      <origin rpy="0 0 0" xyz="1.866E-06 -0.022047 0.026133"/>
      <mass value="0.023013"/>
      <inertia ixx="6.0949E-06" ixy="-6.0665E-11" ixz="7.191E-11" iyy="6.0197E-06" iyz="2.7531E-06" izz="5.0784E-06"/>
    </inertial>
    <visual>
      <geometry>
        <mesh filename="package://xarm_description/meshes/gripper/xarm/right_inner_knuckle.stl"/>
      </geometry>
      <origin rpy="0 0 0" xyz="0 0 0"/>
      <material name="Silver"/>
    </visual>
    <collision>
      <geometry>
        <mesh filename="package://xarm_description/meshes/gripper/xarm/right_inner_knuckle.stl"/>
      </geometry>
      <origin rpy="0 0 0" xyz="0 0 0"/>
    </collision>
  </link>
  <joint name="right_inner_knuckle_joint" type="revolute">
    <origin rpy="0 0 0" xyz="0 -0.02 0.074098"/>
    <parent link="xarm_gripper_base_link"/>
    <child link="right_inner_knuckle"/>
    <axis xyz="-1 0 0"/>
    <limit effort="50" lower="0" upper="0.85" velocity="2"/>
    <mimic joint="drive_joint" multiplier="1" offset="0"/>
  </joint>
  <link name="link_tcp"/>
  <joint name="joint_tcp" type="fixed">
    <origin rpy="0 0 0" xyz="0 0 0.172"/>
    <parent link="xarm_gripper_base_link"/>
    <child link="link_tcp"/>
  </joint>
  <transmission name="drive_joint_trans">
    <type>transmission_interface/SimpleTransmission</type>
    <joint name="drive_joint">
      <hardwareInterface>hardware_interface/PositionJointInterface</hardwareInterface>
    </joint>
    <actuator name="drive_joint_motor">
      <hardwareInterface>hardware_interface/PositionJointInterface</hardwareInterface>
      <mechanicalReduction>1</mechanicalReduction>
    </actuator>
  </transmission>
  <gazebo reference="xarm_gripper_base_link">
    <selfCollide>false</selfCollide>
  </gazebo>
  <gazebo reference="left_outer_knuckle">
    <selfCollide>false</selfCollide>
  </gazebo>
  <gazebo reference="left_finger">
    <selfCollide>false</selfCollide>
  </gazebo>
  <gazebo reference="left_inner_knuckle">
    <selfCollide>false</selfCollide>
  </gazebo>
  <gazebo reference="right_outer_knuckle">
    <selfCollide>false</selfCollide>
  </gazebo>
  <gazebo reference="right_finger">
    <selfCollide>false</selfCollide>
  </gazebo>
  <gazebo reference="right_inner_knuckle">
    <selfCollide>false</selfCollide>
  </gazebo>
  <gazebo>
    <plugin filename="libgazebo_mimic_joint_plugin.so" name="left_finger_jointmimic_joint_plugin">
      <joint>drive_joint</joint>
      <mimicJoint>left_finger_joint</mimicJoint>
      <!-- if set to true, PID parameters from "/gazebo_ros_control/pid_gains/${mimic_joint}" are loaded -->
      <hasPID/>
      <multiplier>1.0</multiplier>
      <offset>0</offset>
      <sensitiveness>0.0</sensitiveness>
      <!-- if absolute difference between setpoint and process value is below this threshold, do nothing; 0.0 = disable [rad] -->
      <maxEffort>10.0</maxEffort>
    </plugin>
  </gazebo>
  <gazebo>
    <plugin filename="libgazebo_mimic_joint_plugin.so" name="left_inner_knuckle_jointmimic_joint_plugin">
      <joint>drive_joint</joint>
      <mimicJoint>left_inner_knuckle_joint</mimicJoint>
      <!-- if set to true, PID parameters from "/gazebo_ros_control/pid_gains/${mimic_joint}" are loaded -->
      <hasPID/>
      <multiplier>1.0</multiplier>
      <offset>0</offset>
      <sensitiveness>0.0</sensitiveness>
      <!-- if absolute difference between setpoint and process value is below this threshold, do nothing; 0.0 = disable [rad] -->
      <maxEffort>10.0</maxEffort>
    </plugin>
  </gazebo>
  <gazebo>
    <plugin filename="libgazebo_mimic_joint_plugin.so" name="right_outer_knuckle_jointmimic_joint_plugin">
      <joint>drive_joint</joint>
      <mimicJoint>right_outer_knuckle_joint</mimicJoint>
      <!-- if set to true, PID parameters from "/gazebo_ros_control/pid_gains/${mimic_joint}" are loaded -->
      <hasPID/>
      <multiplier>1.0</multiplier>
      <offset>0</offset>
      <sensitiveness>0.0</sensitiveness>
      <!-- if absolute difference between setpoint and process value is below this threshold, do nothing; 0.0 = disable [rad] -->
      <maxEffort>10.0</maxEffort>
    </plugin>
  </gazebo>
  <gazebo>
    <plugin filename="libgazebo_mimic_joint_plugin.so" name="right_finger_jointmimic_joint_plugin">
      <joint>drive_joint</joint>
      <mimicJoint>right_finger_joint</mimicJoint>
      <!-- if set to true, PID parameters from "/gazebo_ros_control/pid_gains/${mimic_joint}" are loaded -->
      <hasPID/>
      <multiplier>1.0</multiplier>
      <offset>0</offset>
      <sensitiveness>0.0</sensitiveness>
      <!-- if absolute difference between setpoint and process value is below this threshold, do nothing; 0.0 = disable [rad] -->
      <maxEffort>10.0</maxEffort>
    </plugin>
  </gazebo>
  <gazebo>
    <plugin filename="libgazebo_mimic_joint_plugin.so" name="right_inner_knuckle_jointmimic_joint_plugin">
      <joint>drive_joint</joint>
      <mimicJoint>right_inner_knuckle_joint</mimicJoint>
      <!-- if set to true, PID parameters from "/gazebo_ros_control/pid_gains/${mimic_joint}" are loaded -->
      <hasPID/>
      <multiplier>1.0</multiplier>
      <offset>0</offset>
      <sensitiveness>0.0</sensitiveness>
      <!-- if absolute difference between setpoint and process value is below this threshold, do nothing; 0.0 = disable [rad] -->
      <maxEffort>10.0</maxEffort>
    </plugin>
  </gazebo>
  <!-- Insert at the end of xarm_device_macro.xacro -->
  <material name="zed_mat">
    <color rgba="0.8 0.8 0.8 1.0"/>
  </material>
  <material name="zedm_mat">
    <color rgba="0 0 0 1.0"/>
  </material>
  <material name="zed2_mat">
    <color rgba="0.25 0.25 0.25 1.0"/>
  </material>
  <material name="zed2i_mat">
    <color rgba="0.25 0.25 0.25 1.0"/>
  </material>
  <material name="zedx_mat">
    <color rgba="0.25 0.25 0.25 1.0"/>
  </material>
  <material name="zedxm_mat">
    <color rgba="0.25 0.25 0.25 1.0"/>
  </material>
  <material name="virtual_mat">
    <color rgba="0.25 0.25 0.25 1.0"/>
  </material>
  <material name="zedxonegs_mat">
    <color rgba="0.25 0.25 0.25 1.0"/>
  </material>
  <material name="zedxone4k_mat">
    <color rgba="0.25 0.25 0.25 1.0"/>
  </material>
  <joint name="zed_fixed_joint" type="fixed">
    <parent link="camera_center_link"/>
    <child link="zed_camera_link"/>
    <origin rpy="0 0 1.5707" xyz="0 -.0143 -.01325"/>
    <!-- The back of the camera is at y = -0.0218 -->
  </joint>
  <!-- Camera mounting point (the threaded screw hole in the bottom) -->
  <link name="zed_camera_link"/>
  <!-- Camera Center -->
  <link name="zed_camera_center">
    <visual>
      <origin rpy="0 0 0" xyz="0.0 0 0.0"/>
      <geometry>
        <mesh filename="file:///home/yashas/dev_ws/install/dim_cpp/share/dim_cpp/meshes/zedm.stl"/>
      </geometry>
      <material name="zedm_mat"/>
    </visual>
    <collision>
      <origin rpy="0 0 0" xyz="0.0 0 0.0"/>
      <geometry>
        <mesh filename="file:///home/yashas/dev_ws/install/dim_cpp/share/dim_cpp/meshes/zedm.stl"/>
      </geometry>
    </collision>
  </link>
  <joint name="zed_camera_center_joint" type="fixed">
    <parent link="zed_camera_link"/>
    <child link="zed_camera_center"/>
    <origin rpy="0 0.0 0" xyz="0 0 0.01325"/>
  </joint>
  <!-- Left Camera -->
  <link name="zed_left_camera_frame">
  </link>
  <joint name="zed_left_camera_joint" type="fixed">
    <parent link="zed_camera_center"/>
    <child link="zed_left_camera_frame"/>
    <origin rpy="0 0 0" xyz="0.0 0.0315 0"/>
  </joint>
  <link name="zed_left_camera_optical_frame"/>
  <joint name="zed_left_camera_optical_joint" type="fixed">
    <origin rpy="-1.5707963267948966 0.0 -1.5707963267948966" xyz="0 0 0"/>
    <parent link="zed_left_camera_frame"/>
    <child link="zed_left_camera_optical_frame"/>
  </joint>
  <!-- Right Camera -->
  <link name="zed_right_camera_frame">
  </link>
  <joint name="zed_right_camera_joint" type="fixed">
    <parent link="zed_camera_center"/>
    <child link="zed_right_camera_frame"/>
    <origin rpy="0 0 0" xyz="0.0 -0.0315 0"/>
  </joint>
  <link name="zed_right_camera_optical_frame"/>
  <joint name="zed_right_camera_optical_joint" type="fixed">
    <origin rpy="-1.5707963267948966 0.0 -1.5707963267948966" xyz="0 0 0"/>
    <parent link="zed_right_camera_frame"/>
    <child link="zed_right_camera_optical_frame"/>
  </joint>
  <drake:collision_filter_group name="no_collide">
    <drake:member link="base_center"/>
    <drake:member link="devkit_base_link"/>
    <drake:member link="pillar_platform"/>
    <drake:member link="piper_angled_mount"/>
    <drake:member link="zed_camera_link"/>
    <drake:member link="zed_camera_center"/>
    <drake:member link="zed_left_camera_frame"/>
    <drake:member link="zed_left_camera_optical_frame"/>
    <drake:member link="zed_right_camera_frame"/>
    <drake:member link="zed_right_camera_optical_frame"/>
    <drake:member link="pan_tilt_pan"/>
    <drake:member link="pan_tilt_head"/>
    <drake:member link="pan_tilt_base"/>
    <drake:ignored_collision_filter_group name="no_collide"/>
  </drake:collision_filter_group>
</robot>
